Workbook
Name sel_loc: 'Supuestos'!$B$3
Name sel_locIdx: 'Supuestos'!$C$3
Name sel_cfg: 'Supuestos'!$B$4
Name sel_cfgIdx: 'Supuestos'!$C$4
Name sel_escIdx: 'Supuestos'!$C$5
Name cfg_units: 'Supuestos'!$K$3:$K$7
Name esc_salarios: 'Supuestos'!$E$11
Name esc_retorno: 'Supuestos'!$E$12
Name esc_inflacion: 'Supuestos'!$E$13
Name esc_retraso: 'Supuestos'!$E$14
Name esc_probMatch: 'Supuestos'!$E$15
Name esc_apreciacion: 'Supuestos'!$E$16
Name esc_tasaHipoteca: 'Supuestos'!$E$17
Name esc_gastos: 'Supuestos'!$E$18
Name esc_probExamenes: 'Supuestos'!$E$19
Name general_anioInicio: 'Supuestos'!$C$54
Name general_horizonte: 'Supuestos'!$C$55
Name general_edad: 'Supuestos'!$C$56
Name general_inflacion: 'Supuestos'!$C$57
Name general_retornoInversion: 'Supuestos'!$C$58
Name general_retornoEfectivo: 'Supuestos'!$C$59
Name general_tasaAhorro: 'Supuestos'!$C$60
Name general_reservaMeses: 'Supuestos'!$C$61
Name general_tasaDeudaConsumo: 'Supuestos'!$C$62
Name personal_tarifaHora: 'Supuestos'!$C$63
Name personal_horasSemana: 'Supuestos'!$C$64
Name personal_liquidoInicial: 'Supuestos'!$C$65
Name personal_retiroInicial: 'Supuestos'!$C$66
Name personal_irsSaldo: 'Supuestos'!$C$67
Name personal_irsPagoMensual: 'Supuestos'!$C$68
Name personal_deudaEstudiantil: 'Supuestos'!$C$69
Name personal_tasaDeudaEstudiantil: 'Supuestos'!$C$70
Name personal_deudaEsFederal: 'Supuestos'!$C$71
Name personal_aporte403bPct: 'Supuestos'!$C$72
Name personal_match403bPct: 'Supuestos'!$C$73
Name personal_rothAnual: 'Supuestos'!$C$74
Name personal_bsnFin: 'Supuestos'!$C$75
Name personal_bsnCostoRestante: 'Supuestos'!$C$76
Name personal_bsnAumento: 'Supuestos'!$C$77
Name personal_llcActivo: 'Supuestos'!$C$78
Name personal_llcNeto: 'Supuestos'!$C$79
Name personal_llcCrecimiento: 'Supuestos'!$C$80
Name personal_aporteFamiliaMensual: 'Supuestos'!$C$81
Name personal_costoMudanzaInicial: 'Supuestos'!$C$82
Name impuestos_deduccionEstandar: 'Supuestos'!$C$83
Name impuestos_ssTasa: 'Supuestos'!$C$84
Name impuestos_ssTope: 'Supuestos'!$C$85
Name impuestos_medicareTasa: 'Supuestos'!$C$86
Name impuestos_medicareAdicional: 'Supuestos'!$C$87
Name impuestos_medicareUmbral: 'Supuestos'!$C$88
Name impuestos_qbiUmbral: 'Supuestos'!$C$89
Name impuestos_qbiRango: 'Supuestos'!$C$90
Name impuestos_scorpSalarioPct: 'Supuestos'!$C$91
Name impuestos_scorpCostoAnual: 'Supuestos'!$C$92
Name impuestos_nyDeduccion: 'Supuestos'!$C$93
Name impuestos_ohTasa: 'Supuestos'!$C$94
Name impuestos_ohExento: 'Supuestos'!$C$95
Name impuestos_ohMunicipal: 'Supuestos'!$C$96
Name retiro_limite403b: 'Supuestos'!$C$97
Name prestamos_tasaFederalPosgrado: 'Supuestos'!$C$98

Sheet Supuestos
A1: Supuestos del modelo (editar celdas azules)
A2: Fuente única: supuestos.json. Cambiar aquí recalcula todo el libro. Porcentajes como fracción (0.07 = 7%). Booleanos 1/0. | H2: Ubicaciones | J2: Configuraciones | K2: Unid. rentadas | L2: Escenarios
A3: Ubicación (id) | B3: dfw | C3: =MATCH(B3,$H$3:$H$7,0) | H3: miami | I3: Miami / Sur de Florida | J3: duplex | K3: 0 | L3: pesimista
A4: Configuración de vivienda | B4: duplex | C4: =MATCH(B4,$J$3:$J$7,0) | H4: dfw | I4: Dallas–Fort Worth | J4: inlaw | K4: 0 | L4: base
A5: Escenario | B5: base | C5: =MATCH(B5,$L$3:$L$5,0) | H5: houston | I5: Houston | J5: dosCasas | K5: 0 | L5: optimista
H6: nyc | I6: Nueva York (Queens/Bronx) | J6: casaAdu | K6: 0
H7: cleveland | I7: Cleveland / NE de Ohio | J7: multi | K7: 2
A9: Ajustes por escenario
A10: Ajuste | B10: pesimista | C10: base | D10: optimista | E10: Activo
A11: salarios | B11: 0.92 | C11: 1 | D11: 1.06 | E11: =CHOOSE(sel_escIdx,B11,C11,D11)
A12: retorno | B12: -0.02 | C12: 0 | D12: 0.015 | E12: =CHOOSE(sel_escIdx,B12,C12,D12)
A13: inflacion | B13: 0.01 | C13: 0 | D13: -0.005 | E13: =CHOOSE(sel_escIdx,B13,C13,D13)
A14: retraso | B14: 0.5 | C14: 0 | D14: 0 | E14: =CHOOSE(sel_escIdx,B14,C14,D14)
A15: probMatch | B15: -0.15 | C15: 0 | D15: 0.1 | E15: =CHOOSE(sel_escIdx,B15,C15,D15)
A16: apreciacion | B16: -0.02 | C16: 0 | D16: 0.01 | E16: =CHOOSE(sel_escIdx,B16,C16,D16)
A17: tasaHipoteca | B17: 0.01 | C17: 0 | D17: -0.0125 | E17: =CHOOSE(sel_escIdx,B17,C17,D17)
A18: gastos | B18: 1.08 | C18: 1 | D18: 0.96 | E18: =CHOOSE(sel_escIdx,B18,C18,D18)
A19: probExamenes | B19: -0.1 | C19: 0 | D19: 0.08 | E19: =CHOOSE(sel_escIdx,B19,C19,D19)
A21: Parámetros efectivos (escenario aplicado) | E21: Brackets federales 2026 (soltero) [hasta, tasa] | I21: Brackets estado de NY (soltero, aprox. 2026) | M21: Impuesto municipal NYC
A22: Inflación efectiva | B22: g_inf | C22: =general_inflacion+esc_inflacion | E22: Desde | F22: Tasa | G22: Δ tasa | I22: Desde | J22: Tasa | K22: Δ tasa | M22: Desde | N22: Tasa | O22: Δ tasa
A23: Retorno efectivo | B23: g_ret | C23: =general_retornoInversion+esc_retorno | E23: 0 | F23: 0.1 | G23: =F23 | I23: 0 | J23: 0.039 | K23: =J23 | M23: 0 | N23: 0.03078 | O23: =N23
A24: Retorno efectivo HYSA | B24: g_cash | C24: =general_retornoEfectivo | E24: 12400 | F24: 0.12 | G24: =F24-F23 | I24: 8500 | J24: 0.044 | K24: =J24-J23 | M24: 12000 | N24: 0.03762 | O24: =N24-N23
A25: Apreciación efectiva | B25: g_appr | C25: =vivienda_apreciacion+esc_apreciacion | E25: 50400 | F25: 0.22 | G25: =F25-F24 | I25: 11700 | J25: 0.0515 | K25: =J25-J24 | M25: 25000 | N25: 0.03819 | O25: =N25-N24
A26: Tasa hipotecaria efectiva | B26: g_mortRate | C26: =MAX(0.01,vivienda_tasaHipoteca+esc_tasaHipoteca) | E26: 105700 | F26: 0.24 | G26: =F26-F25 | I26: 13900 | J26: 0.054 | K26: =J26-J25 | M26: 50000 | N26: 0.03876 | O26: =N26-N25
A27: Multiplicador salarios | B27: g_salMult | C27: =esc_salarios | E27: 201775 | F27: 0.32 | G27: =F27-F26 | I27: 80650 | J27: 0.059 | K27: =J27-J26
A28: Multiplicador gastos | B28: g_gastos | C28: =esc_gastos | E28: 256225 | F28: 0.35 | G28: =F28-F27 | I28: 215400 | J28: 0.0685 | K28: =J28-J27
E29: 640600 | F29: 0.37 | G29: =F29-F28 | I29: 1077550 | J29: 0.0965 | K29: =J29-J28
A30: Ubicación activa | I30: 5000000 | J30: 0.103 | K30: =J30-J29
A31: factorRN | C31: =CHOOSE(sel_locIdx,ubic_miami_factorRN,ubic_dfw_factorRN,ubic_houston_factorRN,ubic_nyc_factorRN,ubic_cleveland_factorRN) | I31: 25000000 | J31: 0.109 | K31: =J31-J30
A32: factorMD | C32: =CHOOSE(sel_locIdx,ubic_miami_factorMD,ubic_dfw_factorMD,ubic_houston_factorMD,ubic_nyc_factorMD,ubic_cleveland_factorMD)
A33: residentePGY1 | C33: =CHOOSE(sel_locIdx,ubic_miami_residentePGY1,ubic_dfw_residentePGY1,ubic_houston_residentePGY1,ubic_nyc_residentePGY1,ubic_cleveland_residentePGY1)
A34: gastosVida | C34: =CHOOSE(sel_locIdx,ubic_miami_gastosVida,ubic_dfw_gastosVida,ubic_houston_gastosVida,ubic_nyc_gastosVida,ubic_cleveland_gastosVida)
A35: rentaMensual | C35: =CHOOSE(sel_locIdx,ubic_miami_rentaMensual,ubic_dfw_rentaMensual,ubic_houston_rentaMensual,ubic_nyc_rentaMensual,ubic_cleveland_rentaMensual)
A36: seguroPct | C36: =CHOOSE(sel_locIdx,ubic_miami_seguroPct,ubic_dfw_seguroPct,ubic_houston_seguroPct,ubic_nyc_seguroPct,ubic_cleveland_seguroPct)
A37: impuestoPropPct | C37: =CHOOSE(sel_locIdx,ubic_miami_impuestoPropPct,ubic_dfw_impuestoPropPct,ubic_houston_impuestoPropPct,ubic_nyc_impuestoPropPct,ubic_cleveland_impuestoPropPct)
A38: factorMatch | C38: =CHOOSE(sel_locIdx,ubic_miami_factorMatch,ubic_dfw_factorMatch,ubic_houston_factorMatch,ubic_nyc_factorMatch,ubic_cleveland_factorMatch)
A39: rentaUnidad | C39: =CHOOSE(sel_locIdx,ubic_miami_rentaUnidad,ubic_dfw_rentaUnidad,ubic_houston_rentaUnidad,ubic_nyc_rentaUnidad,ubic_cleveland_rentaUnidad)
A40: precio_duplex | C40: =CHOOSE(sel_locIdx,ubic_miami_precio_duplex,ubic_dfw_precio_duplex,ubic_houston_precio_duplex,ubic_nyc_precio_duplex,ubic_cleveland_precio_duplex)
A41: precio_inlaw | C41: =CHOOSE(sel_locIdx,ubic_miami_precio_inlaw,ubic_dfw_precio_inlaw,ubic_houston_precio_inlaw,ubic_nyc_precio_inlaw,ubic_cleveland_precio_inlaw)
A42: precio_dosCasas | C42: =CHOOSE(sel_locIdx,ubic_miami_precio_dosCasas,ubic_dfw_precio_dosCasas,ubic_houston_precio_dosCasas,ubic_nyc_precio_dosCasas,ubic_cleveland_precio_dosCasas)
...

Sheet Comparativa
A1: Comparativa de caminos (ubicación, vivienda y escenario según la hoja Supuestos)
A2: =CONCATENATE("Ubicación: ",sel_loc," · Vivienda: ",sel_cfg," · Escenario: ",Supuestos!B5)
A4: Año | B4: A1 · Case mgmt → UR payer-side (remoto) | C4: A2 · Bedside ICU (residencia RN experimentado) | D4: A3 · ICU → Travel nurse | E4: A4 · CDI / informática (valora tu MD) | F4: A5 · ICU → charge → nurse manager | G4: A5b · ICU → educador clínico | H4: A6 · Nurse injector / estética | I4: A7 · ICU → CRNA | J4: A7b · ICU → Travel → CRNA | K4: A8 · NP familiar (FNP) | L4: A8b · NP psiquiátrico (PMHNP) | M4: B1 · MD: match al primer intento | N4: B2 · MD: SOAP preliminar → categórico | O4: B3 · MD: no match → match al reintento | P4: B4 · MD: nunca hace match → vuelve a CDI
A5: 2027 | B5: ='A1 cm_ur'!EG33 | C5: ='A2 icu'!EG33 | D5: ='A3 icu_travel'!EG33 | E5: ='A4 cdi'!EG33 | F5: ='A5 manager'!EG33 | G5: ='A5b educador'!EG33 | H5: ='A6 injector'!EG33 | I5: ='A7 crna'!EG33 | J5: ='A7b icu_travel_crna'!EG33 | K5: ='A8 fnp'!EG33 | L5: ='A8b pmhnp'!EG33 | M5: ='B1 md_match1'!EG33 | N5: ='B2 md_soap_prelim'!EG33 | O5: ='B3 md_reintento'!EG33 | P5: ='B4 md_fallo'!EG33
A6: 2028 | B6: ='A1 cm_ur'!EG34 | C6: ='A2 icu'!EG34 | D6: ='A3 icu_travel'!EG34 | E6: ='A4 cdi'!EG34 | F6: ='A5 manager'!EG34 | G6: ='A5b educador'!EG34 | H6: ='A6 injector'!EG34 | I6: ='A7 crna'!EG34 | J6: ='A7b icu_travel_crna'!EG34 | K6: ='A8 fnp'!EG34 | L6: ='A8b pmhnp'!EG34 | M6: ='B1 md_match1'!EG34 | N6: ='B2 md_soap_prelim'!EG34 | O6: ='B3 md_reintento'!EG34 | P6: ='B4 md_fallo'!EG34
A7: 2029 | B7: ='A1 cm_ur'!EG35 | C7: ='A2 icu'!EG35 | D7: ='A3 icu_travel'!EG35 | E7: ='A4 cdi'!EG35 | F7: ='A5 manager'!EG35 | G7: ='A5b educador'!EG35 | H7: ='A6 injector'!EG35 | I7: ='A7 crna'!EG35 | J7: ='A7b icu_travel_crna'!EG35 | K7: ='A8 fnp'!EG35 | L7: ='A8b pmhnp'!EG35 | M7: ='B1 md_match1'!EG35 | N7: ='B2 md_soap_prelim'!EG35 | O7: ='B3 md_reintento'!EG35 | P7: ='B4 md_fallo'!EG35
A8: 2030 | B8: ='A1 cm_ur'!EG36 | C8: ='A2 icu'!EG36 | D8: ='A3 icu_travel'!EG36 | E8: ='A4 cdi'!EG36 | F8: ='A5 manager'!EG36 | G8: ='A5b educador'!EG36 | H8: ='A6 injector'!EG36 | I8: ='A7 crna'!EG36 | J8: ='A7b icu_travel_crna'!EG36 | K8: ='A8 fnp'!EG36 | L8: ='A8b pmhnp'!EG36 | M8: ='B1 md_match1'!EG36 | N8: ='B2 md_soap_prelim'!EG36 | O8: ='B3 md_reintento'!EG36 | P8: ='B4 md_fallo'!EG36
A9: 2031 | B9: ='A1 cm_ur'!EG37 | C9: ='A2 icu'!EG37 | D9: ='A3 icu_travel'!EG37 | E9: ='A4 cdi'!EG37 | F9: ='A5 manager'!EG37 | G9: ='A5b educador'!EG37 | H9: ='A6 injector'!EG37 | I9: ='A7 crna'!EG37 | J9: ='A7b icu_travel_crna'!EG37 | K9: ='A8 fnp'!EG37 | L9: ='A8b pmhnp'!EG37 | M9: ='B1 md_match1'!EG37 | N9: ='B2 md_soap_prelim'!EG37 | O9: ='B3 md_reintento'!EG37 | P9: ='B4 md_fallo'!EG37
A10: 2032 | B10: ='A1 cm_ur'!EG38 | C10: ='A2 icu'!EG38 | D10: ='A3 icu_travel'!EG38 | E10: ='A4 cdi'!EG38 | F10: ='A5 manager'!EG38 | G10: ='A5b educador'!EG38 | H10: ='A6 injector'!EG38 | I10: ='A7 crna'!EG38 | J10: ='A7b icu_travel_crna'!EG38 | K10: ='A8 fnp'!EG38 | L10: ='A8b pmhnp'!EG38 | M10: ='B1 md_match1'!EG38 | N10: ='B2 md_soap_prelim'!EG38 | O10: ='B3 md_reintento'!EG38 | P10: ='B4 md_fallo'!EG38
A11: 2033 | B11: ='A1 cm_ur'!EG39 | C11: ='A2 icu'!EG39 | D11: ='A3 icu_travel'!EG39 | E11: ='A4 cdi'!EG39 | F11: ='A5 manager'!EG39 | G11: ='A5b educador'!EG39 | H11: ='A6 injector'!EG39 | I11: ='A7 crna'!EG39 | J11: ='A7b icu_travel_crna'!EG39 | K11: ='A8 fnp'!EG39 | L11: ='A8b pmhnp'!EG39 | M11: ='B1 md_match1'!EG39 | N11: ='B2 md_soap_prelim'!EG39 | O11: ='B3 md_reintento'!EG39 | P11: ='B4 md_fallo'!EG39
A12: 2034 | B12: ='A1 cm_ur'!EG40 | C12: ='A2 icu'!EG40 | D12: ='A3 icu_travel'!EG40 | E12: ='A4 cdi'!EG40 | F12: ='A5 manager'!EG40 | G12: ='A5b educador'!EG40 | H12: ='A6 injector'!EG40 | I12: ='A7 crna'!EG40 | J12: ='A7b icu_travel_crna'!EG40 | K12: ='A8 fnp'!EG40 | L12: ='A8b pmhnp'!EG40 | M12: ='B1 md_match1'!EG40 | N12: ='B2 md_soap_prelim'!EG40 | O12: ='B3 md_reintento'!EG40 | P12: ='B4 md_fallo'!EG40
A13: 2035 | B13: ='A1 cm_ur'!EG41 | C13: ='A2 icu'!EG41 | D13: ='A3 icu_travel'!EG41 | E13: ='A4 cdi'!EG41 | F13: ='A5 manager'!EG41 | G13: ='A5b educador'!EG41 | H13: ='A6 injector'!EG41 | I13: ='A7 crna'!EG41 | J13: ='A7b icu_travel_crna'!EG41 | K13: ='A8 fnp'!EG41 | L13: ='A8b pmhnp'!EG41 | M13: ='B1 md_match1'!EG41 | N13: ='B2 md_soap_prelim'!EG41 | O13: ='B3 md_reintento'!EG41 | P13: ='B4 md_fallo'!EG41
A14: 2036 | B14: ='A1 cm_ur'!EG42 | C14: ='A2 icu'!EG42 | D14: ='A3 icu_travel'!EG42 | E14: ='A4 cdi'!EG42 | F14: ='A5 manager'!EG42 | G14: ='A5b educador'!EG42 | H14: ='A6 injector'!EG42 | I14: ='A7 crna'!EG42 | J14: ='A7b icu_travel_crna'!EG42 | K14: ='A8 fnp'!EG42 | L14: ='A8b pmhnp'!EG42 | M14: ='B1 md_match1'!EG42 | N14: ='B2 md_soap_prelim'!EG42 | O14: ='B3 md_reintento'!EG42 | P14: ='B4 md_fallo'!EG42
A15: 2037 | B15: ='A1 cm_ur'!EG43 | C15: ='A2 icu'!EG43 | D15: ='A3 icu_travel'!EG43 | E15: ='A4 cdi'!EG43 | F15: ='A5 manager'!EG43 | G15: ='A5b educador'!EG43 | H15: ='A6 injector'!EG43 | I15: ='A7 crna'!EG43 | J15: ='A7b icu_travel_crna'!EG43 | K15: ='A8 fnp'!EG43 | L15: ='A8b pmhnp'!EG43 | M15: ='B1 md_match1'!EG43 | N15: ='B2 md_soap_prelim'!EG43 | O15: ='B3 md_reintento'!EG43 | P15: ='B4 md_fallo'!EG43
A16: 2038 | B16: ='A1 cm_ur'!EG44 | C16: ='A2 icu'!EG44 | D16: ='A3 icu_travel'!EG44 | E16: ='A4 cdi'!EG44 | F16: ='A5 manager'!EG44 | G16: ='A5b educador'!EG44 | H16: ='A6 injector'!EG44 | I16: ='A7 crna'!EG44 | J16: ='A7b icu_travel_crna'!EG44 | K16: ='A8 fnp'!EG44 | L16: ='A8b pmhnp'!EG44 | M16: ='B1 md_match1'!EG44 | N16: ='B2 md_soap_prelim'!EG44 | O16: ='B3 md_reintento'!EG44 | P16: ='B4 md_fallo'!EG44
... A24: 2046 | B24: ='A1 cm_ur'!EG52 | C24: ='A2 icu'!EG52 | D24: ='A3 icu_travel'!EG52 | E24: ='A4 cdi'!EG52 | F24: ='A5 manager'!EG52 | G24: ='A5b educador'!EG52 | H24: ='A6 injector'!EG52 | I24: ='A7 crna'!EG52 | J24: ='A7b icu_travel_crna'!EG52 | K24: ='A8 fnp'!EG52 | L24: ='A8b pmhnp'!EG52 | M24: ='B1 md_match1'!EG52 | N24: ='B2 md_soap_prelim'!EG52 | O24: ='B3 md_reintento'!EG52 | P24: ='B4 md_fallo'!EG52
A26: Patrimonio año 10 | B26: =B14 | C26: =C14 | D26: =D14 | E26: =E14 | F26: =F14 | G26: =G14 | H26: =H14 | I26: =I14 | ... P26: =P14
A27: Patrimonio año 20 | B27: =B24 | C27: =C24 | D27: =D24 | E27: =E24 | F27: =F24 | G27: =G24 | H27: =H24 | I27: =I24 | ... P27: =P24
A28: Año compra vivienda | B28: =IF('A1 cm_ur'!BC52="","no viable",'A1 cm_ur'!BC52) | C28: =IF('A2 icu'!BC52="","no viable",'A2 icu'!BC52) | D28: =IF('A3 icu_travel'!BC52="","no viable",'A3 icu_travel'!BC52) | E28: =IF('A4 cdi'!BC52="","no viable",'A4 cdi'!BC52) | F28: =IF('A5 manager'!BC52="","no viable",'A5 manager'!BC52) | G28: =IF('A5b educador'!BC52="","no viable",'A5b educador'!BC52) | H28: =IF('A6 injector'!BC52="","no viable",'A6 injector'!BC52) | I28: =IF('A7 crna'!BC52="","no viable",'A7 crna'!BC52) | J28: =IF('A7b icu_travel_crna'!BC52="","no viable",'A7b icu_travel_crna'!BC52) | K28: =IF('A8 fnp'!BC52="","no viable",'A8 fnp'!BC52) | L28: =IF('A8b pmhnp'!BC52="","no viable",'A8b pmhnp'!BC52) | M28: =IF('B1 md_match1'!BC52="","no viable",'B1 md_match1'!BC52) | N28: =IF('B2 md_soap_prelim'!BC52="","no viable",'B2 md_soap_prelim'!BC52) | O28: =IF('B3 md_reintento'!BC52="","no viable",'B3 md_reintento'!BC52) | P28: =IF('B4 md_fallo'!BC52="","no viable",'B4 md_fallo'!BC52)
A29: Año vivienda pagada | B29: =IF('A1 cm_ur'!EE52="","—",'A1 cm_ur'!EE52) | C29: =IF('A2 icu'!EE52="","—",'A2 icu'!EE52) | D29: =IF('A3 icu_travel'!EE52="","—",'A3 icu_travel'!EE52) | E29: =IF('A4 cdi'!EE52="","—",'A4 cdi'!EE52) | F29: =IF('A5 manager'!EE52="","—",'A5 manager'!EE52) | G29: =IF('A5b educador'!EE52="","—",'A5b educador'!EE52) | H29: =IF('A6 injector'!EE52="","—",'A6 injector'!EE52) | I29: =IF('A7 crna'!EE52="","—",'A7 crna'!EE52) | J29: =IF('A7b icu_travel_crna'!EE52="","—",'A7b icu_travel_crna'!EE52) | K29: =IF('A8 fnp'!EE52="","—",'A8 fnp'!EE52) | L29: =IF('A8b pmhnp'!EE52="","—",'A8b pmhnp'!EE52) | M29: =IF('B1 md_match1'!EE52="","—",'B1 md_match1'!EE52) | N29: =IF('B2 md_soap_prelim'!EE52="","—",'B2 md_soap_prelim'!EE52) | O29: =IF('B3 md_reintento'!EE52="","—",'B3 md_reintento'!EE52) | P29: =IF('B4 md_fallo'!EE52="","—",'B4 md_fallo'!EE52)
A30: Deuda máxima | B30: =MAX('A1 cm_ur'!EF33:EF52) | C30: =MAX('A2 icu'!EF33:EF52) | D30: =MAX('A3 icu_travel'!EF33:EF52) | E30: =MAX('A4 cdi'!EF33:EF52) | F30: =MAX('A5 manager'!EF33:EF52) | G30: =MAX('A5b educador'!EF33:EF52) | H30: =MAX('A6 injector'!EF33:EF52) | I30: =MAX('A7 crna'!EF33:EF52) | J30: =MAX('A7b icu_travel_crna'!EF33:EF52) | K30: =MAX('A8 fnp'!EF33:EF52) | L30: =MAX('A8b pmhnp'!EF33:EF52) | M30: =MAX('B1 md_match1'!EF33:EF52) | N30: =MAX('B2 md_soap_prelim'!EF33:EF52) | O30: =MAX('B3 md_reintento'!EF33:EF52) | P30: =MAX('B4 md_fallo'!EF33:EF52)
A31: Ranking (año 20) | B31: =RANK(B24,$B$24:$P$24) | C31: =RANK(C24,$B$24:$P$24) | D31: =RANK(D24,$B$24:$P$24) | E31: =RANK(E24,$B$24:$P$24) | F31: =RANK(F24,$B$24:$P$24) | G31: =RANK(G24,$B$24:$P$24) | H31: =RANK(H24,$B$24:$P$24) | I31: =RANK(I24,$B$24:$P$24) | ... P31: =RANK(P24,$B$24:$P$24)
A34: Cruces: año desde el cual el camino de la FILA supera permanentemente al de la COLUMNA
A35: Camino | B35: A1 | C35: A2 | D35: A3 | E35: A4 | F35: A5 | G35: A5b | H35: A6 | I35: A7 | J35: A7b | K35: A8 | L35: A8b | M35: B1 | N35: B2 | O35: B3 | P35: B4
A36: A1 · Case mgmt → UR payer-side (remoto) | B36: — | C36: =IF(SUMPRODUCT(--(B$5:B$24<=C$5:C$24))=0,"siempre",IF(LOOKUP(2,1/(B$5:B$24<=C$5:C$24),$A$5:$A$24)>=2046,"nunca",LOOKUP(2,1/(B$5:B$24<=C$5:C$24),$A$5:$A$24)+1)) | D36: =IF(SUMPRODUCT(--(B$5:B$24<=D$5:D$24))=0,"siempre",IF(LOOKUP(2,1/(B$5:B$24<=D$5:D$24),$A$5:$A$24)>=2046,"nunca",LOOKUP(2,1/(B$5:B$24<=D$5:D$24),$A$5:$A$24)+1)) | E36: =IF(SUMPRODUCT(--(B$5:B$24<=E$5:E$24))=0,"siempre",IF(LOOKUP(2,1/(B$5:B$24<=E$5:E$24),$A$5:$A$24)>=2046,"nunca",LOOKUP(2,1/(B$5:B$24<=E$5:E$24),$A$5:$A$24)+1)) | F36: =IF(SUMPRODUCT(--(B$5:B$24<=F$5:F$24))=0,"siempre",IF(LOOKUP(2,1/(B$5:B$24<=F$5:F$24),$A$5:$A$24)>=2046,"nunca",LOOKUP(2,1/(B$5:B$24<=F$5:F$24),$A$5:$A$24)+1)) | G36: =IF(SUMPRODUCT(--(B$5:B$24<=G$5:G$24))=0,"siempre",IF(LOOKUP(2,1/(B$5:B$24<=G$5:G$24),$A$5:$A$24)>=2046,"nunca",LOOKUP(2,1/(B$5:B$24<=G$5:G$24),$A$5:$A$24)+1)) | H36: =IF(SUMPRODUCT(--(B$5:B$24<=H$5:H$24))=0,"siempre",IF(LOOKUP(2,1/(B$5:B$24<=H$5:H$24),$A$5:$A$24)>=2046,"nunca",LOOKUP(2,1/(B$5:B$24<=H$5:H$24),$A$5:$A$24)+1)) | I36: =IF(SUMPRODUCT(--(B$5:B$24<=I$5:I$24))=0,"siempre",IF(LOOKUP(2,1/(B$5:B$24<=I$5:I$24),$A$5:$A$24)>=2046,"nunca",LOOKUP(2,1/(B$5:B$24<=I$5:I$24),$A$5:$A$24)+1)) | J36: =IF(SUMPRODUCT(--(B$5:B$24<=J$5:J$24))=0,"siempre",IF(LOOKUP(2,1/(B$5:B$24<=J$5:J$24),$A$5:$A$24)>=2046,"nunca",LOOKUP(2,1/(B$5:B$24<=J$5:J$24),$A$5:$A$24)+1)) | K36: =IF(SUMPRODUCT(--(B$5:B$24<=K$5:K$24))=0,"siempre",IF(LOOKUP(2,1/(B$5:B$24<=K$5:K$24),$A$5:$A$24)>=2046,"nunca",LOOKUP(2,1/(B$5:B$24<=K$5:K$24),$A$5:$A$24)+1)) | L36: =IF(SUMPRODUCT(--(B$5:B$24<=L$5:L$24))=0,"siempre",IF(LOOKUP(2,1/(B$5:B$24<=L$5:L$24),$A$5:$A$24)>=2046,"nunca",LOOKUP(2,1/(B$5:B$24<=L$5:L$24),$A$5:$A$24)+1)) | M36: =IF(SUMPRODUCT(--(B$5:B$24<=M$5:M$24))=0,"siempre",IF(LOOKUP(2,1/(B$5:B$24<=M$5:M$24),$A$5:$A$24)>=2046,"nunca",LOOKUP(2,1/(B$5:B$24<=M$5:M$24),$A$5:$A$24)+1)) | N36: =IF(SUMPRODUCT(--(B$5:B$24<=N$5:N$24))=0,"siempre",IF(LOOKUP(2,1/(B$5:B$24<=N$5:N$24),$A$5:$A$24)>=2046,"nunca",LOOKUP(2,1/(B$5:B$24<=N$5:N$24),$A$5:$A$24)+1)) | O36: =IF(SUMPRODUCT(--(B$5:B$24<=O$5:O$24))=0,"siempre",IF(LOOKUP(2,1/(B$5:B$24<=O$5:O$24),$A$5:$A$24)>=2046,"nunca",LOOKUP(2,1/(B$5:B$24<=O$5:O$24),$A$5:$A$24)+1)) | P36: =IF(SUMPRODUCT(--(B$5:B$24<=P$5:P$24))=0,"siempre",IF(LOOKUP(2,1/(B$5:B$24<=P$5:P$24),$A$5:$A$24)>=2046,"nunca",LOOKUP(2,1/(B$5:B$24<=P$5:P$24),$A$5:$A$24)+1))
A37: A2 · Bedside ICU (residencia RN experimentado) | B37: =IF(SUMPRODUCT(--(C$5:C$24<=B$5:B$24))=0,"siempre",IF(LOOKUP(2,1/(C$5:C$24<=B$5:B$24),$A$5:$A$24)>=2046,"nunca",LOOKUP(2,1/(C$5:C$24<=B$5:B$24),$A$5:$A$24)+1)) | C37: — | D37: =IF(SUMPRODUCT(--(C$5:C$24<=D$5:D$24))=0,"siempre",IF(LOOKUP(2,1/(C$5:C$24<=D$5:D$24),$A$5:$A$24)>=2046,"nunca",LOOKUP(2,1/(C$5:C$24<=D$5:D$24),$A$5:$A$24)+1)) | E37: =IF(SUMPRODUCT(--(C$5:C$24<=E$5:E$24))=0,"siempre",IF(LOOKUP(2,1/(C$5:C$24<=E$5:E$24),$A$5:$A$24)>=2046,"nunca",LOOKUP(2,1/(C$5:C$24<=E$5:E$24),$A$5:$A$24)+1)) | F37: =IF(SUMPRODUCT(--(C$5:C$24<=F$5:F$24))=0,"siempre",IF(LOOKUP(2,1/(C$5:C$24<=F$5:F$24),$A$5:$A$24)>=2046,"nunca",LOOKUP(2,1/(C$5:C$24<=F$5:F$24),$A$5:$A$24)+1)) | G37: =IF(SUMPRODUCT(--(C$5:C$24<=G$5:G$24))=0,"siempre",IF(LOOKUP(2,1/(C$5:C$24<=G$5:G$24),$A$5:$A$24)>=2046,"nunca",LOOKUP(2,1/(C$5:C$24<=G$5:G$24),$A$5:$A$24)+1)) | H37: =IF(SUMPRODUCT(--(C$5:C$24<=H$5:H$24))=0,"siempre",IF(LOOKUP(2,1/(C$5:C$24<=H$5:H$24),$A$5:$A$24)>=2046,"nunca",LOOKUP(2,1/(C$5:C$24<=H$5:H$24),$A$5:$A$24)+1)) | I37: =IF(SUMPRODUCT(--(C$5:C$24<=I$5:I$24))=0,"siempre",IF(LOOKUP(2,1/(C$5:C$24<=I$5:I$24),$A$5:$A$24)>=2046,"nunca",LOOKUP(2,1/(C$5:C$24<=I$5:I$24),$A$5:$A$24)+1)) | J37: =IF(SUMPRODUCT(--(C$5:C$24<=J$5:J$24))=0,"siempre",IF(LOOKUP(2,1/(C$5:C$24<=J$5:J$24),$A$5:$A$24)>=2046,"nunca",LOOKUP(2,1/(C$5:C$24<=J$5:J$24),$A$5:$A$24)+1)) | K37: =IF(SUMPRODUCT(--(C$5:C$24<=K$5:K$24))=0,"siempre",IF(LOOKUP(2,1/(C$5:C$24<=K$5:K$24),$A$5:$A$24)>=2046,"nunca",LOOKUP(2,1/(C$5:C$24<=K$5:K$24),$A$5:$A$24)+1)) | L37: =IF(SUMPRODUCT(--(C$5:C$24<=L$5:L$24))=0,"siempre",IF(LOOKUP(2,1/(C$5:C$24<=L$5:L$24),$A$5:$A$24)>=2046,"nunca",LOOKUP(2,1/(C$5:C$24<=L$5:L$24),$A$5:$A$24)+1)) | M37: =IF(SUMPRODUCT(--(C$5:C$24<=M$5:M$24))=0,"siempre",IF(LOOKUP(2,1/(C$5:C$24<=M$5:M$24),$A$5:$A$24)>=2046,"nunca",LOOKUP(2,1/(C$5:C$24<=M$5:M$24),$A$5:$A$24)+1)) | N37: =IF(SUMPRODUCT(--(C$5:C$24<=N$5:N$24))=0,"siempre",IF(LOOKUP(2,1/(C$5:C$24<=N$5:N$24),$A$5:$A$24)>=2046,"nunca",LOOKUP(2,1/(C$5:C$24<=N$5:N$24),$A$5:$A$24)+1)) | O37: =IF(SUMPRODUCT(--(C$5:C$24<=O$5:O$24))=0,"siempre",IF(LOOKUP(2,1/(C$5:C$24<=O$5:O$24),$A$5:$A$24)>=2046,"nunca",LOOKUP(2,1/(C$5:C$24<=O$5:O$24),$A$5:$A$24)+1)) | P37: =IF(SUMPRODUCT(--(C$5:C$24<=P$5:P$24))=0,"siempre",IF(LOOKUP(2,1/(C$5:C$24<=P$5:P$24),$A$5:$A$24)>=2046,"nunca",LOOKUP(2,1/(C$5:C$24<=P$5:P$24),$A$5:$A$24)+1))
A38: A3 · ICU → Travel nurse | B38: =IF(SUMPRODUCT(--(D$5:D$24<=B$5:B$24))=0,"siempre",IF(LOOKUP(2,1/(D$5:D$24<=B$5:B$24),$A$5:$A$24)>=2046,"nunca",LOOKUP(2,1/(D$5:D$24<=B$5:B$24),$A$5:$A$24)+1)) | C38: =IF(SUMPRODUCT(--(D$5:D$24<=C$5:C$24))=0,"siempre",IF(LOOKUP(2,1/(D$5:D$24<=C$5:C$24),$A$5:$A$24)>=2046,"nunca",LOOKUP(2,1/(D$5:D$24<=C$5:C$24),$A$5:$A$24)+1)) | D38: — | E38: =IF(SUMPRODUCT(--(D$5:D$24<=E$5:E$24))=0,"siempre",IF(LOOKUP(2,1/(D$5:D$24<=E$5:E$24),$A$5:$A$24)>=2046,"nunca",LOOKUP(2,1/(D$5:D$24<=E$5:E$24),$A$5:$A$24)+1)) | F38: =IF(SUMPRODUCT(--(D$5:D$24<=F$5:F$24))=0,"siempre",IF(LOOKUP(2,1/(D$5:D$24<=F$5:F$24),$A$5:$A$24)>=2046,"nunca",LOOKUP(2,1/(D$5:D$24<=F$5:F$24),$A$5:$A$24)+1)) | G38: =IF(SUMPRODUCT(--(D$5:D$24<=G$5:G$24))=0,"siempre",IF(LOOKUP(2,1/(D$5:D$24<=G$5:G$24),$A$5:$A$24)>=2046,"nunca",LOOKUP(2,1/(D$5:D$24<=G$5:G$24),$A$5:$A$24)+1)) | H38: =IF(SUMPRODUCT(--(D$5:D$24<=H$5:H$24))=0,"siempre",IF(LOOKUP(2,1/(D$5:D$24<=H$5:H$24),$A$5:$A$24)>=2046,"nunca",LOOKUP(2,1/(D$5:D$24<=H$5:H$24),$A$5:$A$24)+1)) | I38: =IF(SUMPRODUCT(--(D$5:D$24<=I$5:I$24))=0,"siempre",IF(LOOKUP(2,1/(D$5:D$24<=I$5:I$24),$A$5:$A$24)>=2046,"nunca",LOOKUP(2,1/(D$5:D$24<=I$5:I$24),$A$5:$A$24)+1)) | J38: =IF(SUMPRODUCT(--(D$5:D$24<=J$5:J$24))=0,"siempre",IF(LOOKUP(2,1/(D$5:D$24<=J$5:J$24),$A$5:$A$24)>=2046,"nunca",LOOKUP(2,1/(D$5:D$24<=J$5:J$24),$A$5:$A$24)+1)) | K38: =IF(SUMPRODUCT(--(D$5:D$24<=K$5:K$24))=0,"siempre",IF(LOOKUP(2,1/(D$5:D$24<=K$5:K$24),$A$5:$A$24)>=2046,"nunca",LOOKUP(2,1/(D$5:D$24<=K$5:K$24),$A$5:$A$24)+1)) | L38: =IF(SUMPRODUCT(--(D$5:D$24<=L$5:L$24))=0,"siempre",IF(LOOKUP(2,1/(D$5:D$24<=L$5:L$24),$A$5:$A$24)>=2046,"nunca",LOOKUP(2,1/(D$5:D$24<=L$5:L$24),$A$5:$A$24)+1)) | M38: =IF(SUMPRODUCT(--(D$5:D$24<=M$5:M$24))=0,"siempre",IF(LOOKUP(2,1/(D$5:D$24<=M$5:M$24),$A$5:$A$24)>=2046,"nunca",LOOKUP(2,1/(D$5:D$24<=M$5:M$24),$A$5:$A$24)+1)) | N38: =IF(SUMPRODUCT(--(D$5:D$24<=N$5:N$24))=0,"siempre",IF(LOOKUP(2,1/(D$5:D$24<=N$5:N$24),$A$5:$A$24)>=2046,"nunca",LOOKUP(2,1/(D$5:D$24<=N$5:N$24),$A$5:$A$24)+1)) | O38: =IF(SUMPRODUCT(--(D$5:D$24<=O$5:O$24))=0,"siempre",IF(LOOKUP(2,1/(D$5:D$24<=O$5:O$24),$A$5:$A$24)>=2046,"nunca",LOOKUP(2,1/(D$5:D$24<=O$5:O$24),$A$5:$A$24)+1)) | P38: =IF(SUMPRODUCT(--(D$5:D$24<=P$5:P$24))=0,"siempre",IF(LOOKUP(2,1/(D$5:D$24<=P$5:P$24),$A$5:$A$24)>=2046,"nunca",LOOKUP(2,1/(D$5:D$24<=P$5:P$24),$A$5:$A$24)+1))
A39: A4 · CDI / informática (valora tu MD) | B39: =IF(SUMPRODUCT(--(E$5:E$24<=B$5:B$24))=0,"siempre",IF(LOOKUP(2,1/(E$5:E$24<=B$5:B$24),$A$5:$A$24)>=2046,"nunca",LOOKUP(2,1/(E$5:E$24<=B$5:B$24),$A$5:$A$24)+1)) | C39: =IF(SUMPRODUCT(--(E$5:E$24<=C$5:C$24))=0,"siempre",IF(LOOKUP(2,1/(E$5:E$24<=C$5:C$24),$A$5:$A$24)>=2046,"nunca",LOOKUP(2,1/(E$5:E$24<=C$5:C$24),$A$5:$A$24)+1)) | D39: =IF(SUMPRODUCT(--(E$5:E$24<=D$5:D$24))=0,"siempre",IF(LOOKUP(2,1/(E$5:E$24<=D$5:D$24),$A$5:$A$24)>=2046,"nunca",LOOKUP(2,1/(E$5:E$24<=D$5:D$24),$A$5:$A$24)+1)) | E39: — | F39: =IF(SUMPRODUCT(--(E$5:E$24<=F$5:F$24))=0,"siempre",IF(LOOKUP(2,1/(E$5:E$24<=F$5:F$24),$A$5:$A$24)>=2046,"nunca",LOOKUP(2,1/(E$5:E$24<=F$5:F$24),$A$5:$A$24)+1)) | G39: =IF(SUMPRODUCT(--(E$5:E$24<=G$5:G$24))=0,"siempre",IF(LOOKUP(2,1/(E$5:E$24<=G$5:G$24),$A$5:$A$24)>=2046,"nunca",LOOKUP(2,1/(E$5:E$24<=G$5:G$24),$A$5:$A$24)+1)) | H39: =IF(SUMPRODUCT(--(E$5:E$24<=H$5:H$24))=0,"siempre",IF(LOOKUP(2,1/(E$5:E$24<=H$5:H$24),$A$5:$A$24)>=2046,"nunca",LOOKUP(2,1/(E$5:E$24<=H$5:H$24),$A$5:$A$24)+1)) | I39: =IF(SUMPRODUCT(--(E$5:E$24<=I$5:I$24))=0,"siempre",IF(LOOKUP(2,1/(E$5:E$24<=I$5:I$24),$A$5:$A$24)>=2046,"nunca",LOOKUP(2,1/(E$5:E$24<=I$5:I$24),$A$5:$A$24)+1)) | J39: =IF(SUMPRODUCT(--(E$5:E$24<=J$5:J$24))=0,"siempre",IF(LOOKUP(2,1/(E$5:E$24<=J$5:J$24),$A$5:$A$24)>=2046,"nunca",LOOKUP(2,1/(E$5:E$24<=J$5:J$24),$A$5:$A$24)+1)) | K39: =IF(SUMPRODUCT(--(E$5:E$24<=K$5:K$24))=0,"siempre",IF(LOOKUP(2,1/(E$5:E$24<=K$5:K$24),$A$5:$A$24)>=2046,"nunca",LOOKUP(2,1/(E$5:E$24<=K$5:K$24),$A$5:$A$24)+1)) | L39: =IF(SUMPRODUCT(--(E$5:E$24<=L$5:L$24))=0,"siempre",IF(LOOKUP(2,1/(E$5:E$24<=L$5:L$24),$A$5:$A$24)>=2046,"nunca",LOOKUP(2,1/(E$5:E$24<=L$5:L$24),$A$5:$A$24)+1)) | M39: =IF(SUMPRODUCT(--(E$5:E$24<=M$5:M$24))=0,"siempre",IF(LOOKUP(2,1/(E$5:E$24<=M$5:M$24),$A$5:$A$24)>=2046,"nunca",LOOKUP(2,1/(E$5:E$24<=M$5:M$24),$A$5:$A$24)+1)) | N39: =IF(SUMPRODUCT(--(E$5:E$24<=N$5:N$24))=0,"siempre",IF(LOOKUP(2,1/(E$5:E$24<=N$5:N$24),$A$5:$A$24)>=2046,"nunca",LOOKUP(2,1/(E$5:E$24<=N$5:N$24),$A$5:$A$24)+1)) | O39: =IF(SUMPRODUCT(--(E$5:E$24<=O$5:O$24))=0,"siempre",IF(LOOKUP(2,1/(E$5:E$24<=O$5:O$24),$A$5:$A$24)>=2046,"nunca",LOOKUP(2,1/(E$5:E$24<=O$5:O$24),$A$5:$A$24)+1)) | P39: =IF(SUMPRODUCT(--(E$5:E$24<=P$5:P$24))=0,"siempre",IF(LOOKUP(2,1/(E$5:E$24<=P$5:P$24),$A$5:$A$24)>=2046,"nunca",LOOKUP(2,1/(E$5:E$24<=P$5:P$24),$A$5:$A$24)+1))
A40: A5 · ICU → charge → nurse manager | B40: =IF(SUMPRODUCT(--(F$5:F$24<=B$5:B$24))=0,"siempre",IF(LOOKUP(2,1/(F$5:F$24<=B$5:B$24),$A$5:$A$24)>=2046,"nunca",LOOKUP(2,1/(F$5:F$24<=B$5:B$24),$A$5:$A$24)+1)) | C40: =IF(SUMPRODUCT(--(F$5:F$24<=C$5:C$24))=0,"siempre",IF(LOOKUP(2,1/(F$5:F$24<=C$5:C$24),$A$5:$A$24)>=2046,"nunca",LOOKUP(2,1/(F$5:F$24<=C$5:C$24),$A$5:$A$24)+1)) | D40: =IF(SUMPRODUCT(--(F$5:F$24<=D$5:D$24))=0,"siempre",IF(LOOKUP(2,1/(F$5:F$24<=D$5:D$24),$A$5:$A$24)>=2046,"nunca",LOOKUP(2,1/(F$5:F$24<=D$5:D$24),$A$5:$A$24)+1)) | E40: =IF(SUMPRODUCT(--(F$5:F$24<=E$5:E$24))=0,"siempre",IF(LOOKUP(2,1/(F$5:F$24<=E$5:E$24),$A$5:$A$24)>=2046,"nunca",LOOKUP(2,1/(F$5:F$24<=E$5:E$24),$A$5:$A$24)+1)) | F40: — | G40: =IF(SUMPRODUCT(--(F$5:F$24<=G$5:G$24))=0,"siempre",IF(LOOKUP(2,1/(F$5:F$24<=G$5:G$24),$A$5:$A$24)>=2046,"nunca",LOOKUP(2,1/(F$5:F$24<=G$5:G$24),$A$5:$A$24)+1)) | H40: =IF(SUMPRODUCT(--(F$5:F$24<=H$5:H$24))=0,"siempre",IF(LOOKUP(2,1/(F$5:F$24<=H$5:H$24),$A$5:$A$24)>=2046,"nunca",LOOKUP(2,1/(F$5:F$24<=H$5:H$24),$A$5:$A$24)+1)) | I40: =IF(SUMPRODUCT(--(F$5:F$24<=I$5:I$24))=0,"siempre",IF(LOOKUP(2,1/(F$5:F$24<=I$5:I$24),$A$5:$A$24)>=2046,"nunca",LOOKUP(2,1/(F$5:F$24<=I$5:I$24),$A$5:$A$24)+1)) | J40: =IF(SUMPRODUCT(--(F$5:F$24<=J$5:J$24))=0,"siempre",IF(LOOKUP(2,1/(F$5:F$24<=J$5:J$24),$A$5:$A$24)>=2046,"nunca",LOOKUP(2,1/(F$5:F$24<=J$5:J$24),$A$5:$A$24)+1)) | K40: =IF(SUMPRODUCT(--(F$5:F$24<=K$5:K$24))=0,"siempre",IF(LOOKUP(2,1/(F$5:F$24<=K$5:K$24),$A$5:$A$24)>=2046,"nunca",LOOKUP(2,1/(F$5:F$24<=K$5:K$24),$A$5:$A$24)+1)) | L40: =IF(SUMPRODUCT(--(F$5:F$24<=L$5:L$24))=0,"siempre",IF(LOOKUP(2,1/(F$5:F$24<=L$5:L$24),$A$5:$A$24)>=2046,"nunca",LOOKUP(2,1/(F$5:F$24<=L$5:L$24),$A$5:$A$24)+1)) | M40: =IF(SUMPRODUCT(--(F$5:F$24<=M$5:M$24))=0,"siempre",IF(LOOKUP(2,1/(F$5:F$24<=M$5:M$24),$A$5:$A$24)>=2046,"nunca",LOOKUP(2,1/(F$5:F$24<=M$5:M$24),$A$5:$A$24)+1)) | N40: =IF(SUMPRODUCT(--(F$5:F$24<=N$5:N$24))=0,"siempre",IF(LOOKUP(2,1/(F$5:F$24<=N$5:N$24),$A$5:$A$24)>=2046,"nunca",LOOKUP(2,1/(F$5:F$24<=N$5:N$24),$A$5:$A$24)+1)) | O40: =IF(SUMPRODUCT(--(F$5:F$24<=O$5:O$24))=0,"siempre",IF(LOOKUP(2,1/(F$5:F$24<=O$5:O$24),$A$5:$A$24)>=2046,"nunca",LOOKUP(2,1/(F$5:F$24<=O$5:O$24),$A$5:$A$24)+1)) | P40: =IF(SUMPRODUCT(--(F$5:F$24<=P$5:P$24))=0,"siempre",IF(LOOKUP(2,1/(F$5:F$24<=P$5:P$24),$A$5:$A$24)>=2046,"nunca",LOOKUP(2,1/(F$5:F$24<=P$5:P$24),$A$5:$A$24)+1))
A41: A5b · ICU → educador clínico | B41: =IF(SUMPRODUCT(--(G$5:G$24<=B$5:B$24))=0,"siempre",IF(LOOKUP(2,1/(G$5:G$24<=B$5:B$24),$A$5:$A$24)>=2046,"nunca",LOOKUP(2,1/(G$5:G$24<=B$5:B$24),$A$5:$A$24)+1)) | C41: =IF(SUMPRODUCT(--(G$5:G$24<=C$5:C$24))=0,"siempre",IF(LOOKUP(2,1/(G$5:G$24<=C$5:C$24),$A$5:$A$24)>=2046,"nunca",LOOKUP(2,1/(G$5:G$24<=C$5:C$24),$A$5:$A$24)+1)) | D41: =IF(SUMPRODUCT(--(G$5:G$24<=D$5:D$24))=0,"siempre",IF(LOOKUP(2,1/(G$5:G$24<=D$5:D$24),$A$5:$A$24)>=2046,"nunca",LOOKUP(2,1/(G$5:G$24<=D$5:D$24),$A$5:$A$24)+1)) | E41: =IF(SUMPRODUCT(--(G$5:G$24<=E$5:E$24))=0,"siempre",IF(LOOKUP(2,1/(G$5:G$24<=E$5:E$24),$A$5:$A$24)>=2046,"nunca",LOOKUP(2,1/(G$5:G$24<=E$5:E$24),$A$5:$A$24)+1)) | F41: =IF(SUMPRODUCT(--(G$5:G$24<=F$5:F$24))=0,"siempre",IF(LOOKUP(2,1/(G$5:G$24<=F$5:F$24),$A$5:$A$24)>=2046,"nunca",LOOKUP(2,1/(G$5:G$24<=F$5:F$24),$A$5:$A$24)+1)) | G41: — | H41: =IF(SUMPRODUCT(--(G$5:G$24<=H$5:H$24))=0,"siempre",IF(LOOKUP(2,1/(G$5:G$24<=H$5:H$24),$A$5:$A$24)>=2046,"nunca",LOOKUP(2,1/(G$5:G$24<=H$5:H$24),$A$5:$A$24)+1)) | I41: =IF(SUMPRODUCT(--(G$5:G$24<=I$5:I$24))=0,"siempre",IF(LOOKUP(2,1/(G$5:G$24<=I$5:I$24),$A$5:$A$24)>=2046,"nunca",LOOKUP(2,1/(G$5:G$24<=I$5:I$24),$A$5:$A$24)+1)) | J41: =IF(SUMPRODUCT(--(G$5:G$24<=J$5:J$24))=0,"siempre",IF(LOOKUP(2,1/(G$5:G$24<=J$5:J$24),$A$5:$A$24)>=2046,"nunca",LOOKUP(2,1/(G$5:G$24<=J$5:J$24),$A$5:$A$24)+1)) | K41: =IF(SUMPRODUCT(--(G$5:G$24<=K$5:K$24))=0,"siempre",IF(LOOKUP(2,1/(G$5:G$24<=K$5:K$24),$A$5:$A$24)>=2046,"nunca",LOOKUP(2,1/(G$5:G$24<=K$5:K$24),$A$5:$A$24)+1)) | L41: =IF(SUMPRODUCT(--(G$5:G$24<=L$5:L$24))=0,"siempre",IF(LOOKUP(2,1/(G$5:G$24<=L$5:L$24),$A$5:$A$24)>=2046,"nunca",LOOKUP(2,1/(G$5:G$24<=L$5:L$24),$A$5:$A$24)+1)) | M41: =IF(SUMPRODUCT(--(G$5:G$24<=M$5:M$24))=0,"siempre",IF(LOOKUP(2,1/(G$5:G$24<=M$5:M$24),$A$5:$A$24)>=2046,"nunca",LOOKUP(2,1/(G$5:G$24<=M$5:M$24),$A$5:$A$24)+1)) | N41: =IF(SUMPRODUCT(--(G$5:G$24<=N$5:N$24))=0,"siempre",IF(LOOKUP(2,1/(G$5:G$24<=N$5:N$24),$A$5:$A$24)>=2046,"nunca",LOOKUP(2,1/(G$5:G$24<=N$5:N$24),$A$5:$A$24)+1)) | O41: =IF(SUMPRODUCT(--(G$5:G$24<=O$5:O$24))=0,"siempre",IF(LOOKUP(2,1/(G$5:G$24<=O$5:O$24),$A$5:$A$24)>=2046,"nunca",LOOKUP(2,1/(G$5:G$24<=O$5:O$24),$A$5:$A$24)+1)) | P41: =IF(SUMPRODUCT(--(G$5:G$24<=P$5:P$24))=0,"siempre",IF(LOOKUP(2,1/(G$5:G$24<=P$5:P$24),$A$5:$A$24)>=2046,"nunca",LOOKUP(2,1/(G$5:G$24<=P$5:P$24),$A$5:$A$24)+1))
A42: A6 · Nurse injector / estética | B42: =IF(SUMPRODUCT(--(H$5:H$24<=B$5:B$24))=0,"siempre",IF(LOOKUP(2,1/(H$5:H$24<=B$5:B$24),$A$5:$A$24)>=2046,"nunca",LOOKUP(2,1/(H$5:H$24<=B$5:B$24),$A$5:$A$24)+1)) | C42: =IF(SUMPRODUCT(--(H$5:H$24<=C$5:C$24))=0,"siempre",IF(LOOKUP(2,1/(H$5:H$24<=C$5:C$24),$A$5:$A$24)>=2046,"nunca",LOOKUP(2,1/(H$5:H$24<=C$5:C$24),$A$5:$A$24)+1)) | D42: =IF(SUMPRODUCT(--(H$5:H$24<=D$5:D$24))=0,"siempre",IF(LOOKUP(2,1/(H$5:H$24<=D$5:D$24),$A$5:$A$24)>=2046,"nunca",LOOKUP(2,1/(H$5:H$24<=D$5:D$24),$A$5:$A$24)+1)) | E42: =IF(SUMPRODUCT(--(H$5:H$24<=E$5:E$24))=0,"siempre",IF(LOOKUP(2,1/(H$5:H$24<=E$5:E$24),$A$5:$A$24)>=2046,"nunca",LOOKUP(2,1/(H$5:H$24<=E$5:E$24),$A$5:$A$24)+1)) | F42: =IF(SUMPRODUCT(--(H$5:H$24<=F$5:F$24))=0,"siempre",IF(LOOKUP(2,1/(H$5:H$24<=F$5:F$24),$A$5:$A$24)>=2046,"nunca",LOOKUP(2,1/(H$5:H$24<=F$5:F$24),$A$5:$A$24)+1)) | G42: =IF(SUMPRODUCT(--(H$5:H$24<=G$5:G$24))=0,"siempre",IF(LOOKUP(2,1/(H$5:H$24<=G$5:G$24),$A$5:$A$24)>=2046,"nunca",LOOKUP(2,1/(H$5:H$24<=G$5:G$24),$A$5:$A$24)+1)) | H42: — | I42: =IF(SUMPRODUCT(--(H$5:H$24<=I$5:I$24))=0,"siempre",IF(LOOKUP(2,1/(H$5:H$24<=I$5:I$24),$A$5:$A$24)>=2046,"nunca",LOOKUP(2,1/(H$5:H$24<=I$5:I$24),$A$5:$A$24)+1)) | J42: =IF(SUMPRODUCT(--(H$5:H$24<=J$5:J$24))=0,"siempre",IF(LOOKUP(2,1/(H$5:H$24<=J$5:J$24),$A$5:$A$24)>=2046,"nunca",LOOKUP(2,1/(H$5:H$24<=J$5:J$24),$A$5:$A$24)+1)) | K42: =IF(SUMPRODUCT(--(H$5:H$24<=K$5:K$24))=0,"siempre",IF(LOOKUP(2,1/(H$5:H$24<=K$5:K$24),$A$5:$A$24)>=2046,"nunca",LOOKUP(2,1/(H$5:H$24<=K$5:K$24),$A$5:$A$24)+1)) | L42: =IF(SUMPRODUCT(--(H$5:H$24<=L$5:L$24))=0,"siempre",IF(LOOKUP(2,1/(H$5:H$24<=L$5:L$24),$A$5:$A$24)>=2046,"nunca",LOOKUP(2,1/(H$5:H$24<=L$5:L$24),$A$5:$A$24)+1)) | M42: =IF(SUMPRODUCT(--(H$5:H$24<=M$5:M$24))=0,"siempre",IF(LOOKUP(2,1/(H$5:H$24<=M$5:M$24),$A$5:$A$24)>=2046,"nunca",LOOKUP(2,1/(H$5:H$24<=M$5:M$24),$A$5:$A$24)+1)) | N42: =IF(SUMPRODUCT(--(H$5:H$24<=N$5:N$24))=0,"siempre",IF(LOOKUP(2,1/(H$5:H$24<=N$5:N$24),$A$5:$A$24)>=2046,"nunca",LOOKUP(2,1/(H$5:H$24<=N$5:N$24),$A$5:$A$24)+1)) | O42: =IF(SUMPRODUCT(--(H$5:H$24<=O$5:O$24))=0,"siempre",IF(LOOKUP(2,1/(H$5:H$24<=O$5:O$24),$A$5:$A$24)>=2046,"nunca",LOOKUP(2,1/(H$5:H$24<=O$5:O$24),$A$5:$A$24)+1)) | P42: =IF(SUMPRODUCT(--(H$5:H$24<=P$5:P$24))=0,"siempre",IF(LOOKUP(2,1/(H$5:H$24<=P$5:P$24),$A$5:$A$24)>=2046,"nunca",LOOKUP(2,1/(H$5:H$24<=P$5:P$24),$A$5:$A$24)+1))
A43: A7 · ICU → CRNA | B43: =IF(SUMPRODUCT(--(I$5:I$24<=B$5:B$24))=0,"siempre",IF(LOOKUP(2,1/(I$5:I$24<=B$5:B$24),$A$5:$A$24)>=2046,"nunca",LOOKUP(2,1/(I$5:I$24<=B$5:B$24),$A$5:$A$24)+1)) | C43: =IF(SUMPRODUCT(--(I$5:I$24<=C$5:C$24))=0,"siempre",IF(LOOKUP(2,1/(I$5:I$24<=C$5:C$24),$A$5:$A$24)>=2046,"nunca",LOOKUP(2,1/(I$5:I$24<=C$5:C$24),$A$5:$A$24)+1)) | D43: =IF(SUMPRODUCT(--(I$5:I$24<=D$5:D$24))=0,"siempre",IF(LOOKUP(2,1/(I$5:I$24<=D$5:D$24),$A$5:$A$24)>=2046,"nunca",LOOKUP(2,1/(I$5:I$24<=D$5:D$24),$A$5:$A$24)+1)) | E43: =IF(SUMPRODUCT(--(I$5:I$24<=E$5:E$24))=0,"siempre",IF(LOOKUP(2,1/(I$5:I$24<=E$5:E$24),$A$5:$A$24)>=2046,"nunca",LOOKUP(2,1/(I$5:I$24<=E$5:E$24),$A$5:$A$24)+1)) | F43: =IF(SUMPRODUCT(--(I$5:I$24<=F$5:F$24))=0,"siempre",IF(LOOKUP(2,1/(I$5:I$24<=F$5:F$24),$A$5:$A$24)>=2046,"nunca",LOOKUP(2,1/(I$5:I$24<=F$5:F$24),$A$5:$A$24)+1)) | G43: =IF(SUMPRODUCT(--(I$5:I$24<=G$5:G$24))=0,"siempre",IF(LOOKUP(2,1/(I$5:I$24<=G$5:G$24),$A$5:$A$24)>=2046,"nunca",LOOKUP(2,1/(I$5:I$24<=G$5:G$24),$A$5:$A$24)+1)) | H43: =IF(SUMPRODUCT(--(I$5:I$24<=H$5:H$24))=0,"siempre",IF(LOOKUP(2,1/(I$5:I$24<=H$5:H$24),$A$5:$A$24)>=2046,"nunca",LOOKUP(2,1/(I$5:I$24<=H$5:H$24),$A$5:$A$24)+1)) | I43: — | J43: =IF(SUMPRODUCT(--(I$5:I$24<=J$5:J$24))=0,"siempre",IF(LOOKUP(2,1/(I$5:I$24<=J$5:J$24),$A$5:$A$24)>=2046,"nunca",LOOKUP(2,1/(I$5:I$24<=J$5:J$24),$A$5:$A$24)+1)) | K43: =IF(SUMPRODUCT(--(I$5:I$24<=K$5:K$24))=0,"siempre",IF(LOOKUP(2,1/(I$5:I$24<=K$5:K$24),$A$5:$A$24)>=2046,"nunca",LOOKUP(2,1/(I$5:I$24<=K$5:K$24),$A$5:$A$24)+1)) | L43: =IF(SUMPRODUCT(--(I$5:I$24<=L$5:L$24))=0,"siempre",IF(LOOKUP(2,1/(I$5:I$24<=L$5:L$24),$A$5:$A$24)>=2046,"nunca",LOOKUP(2,1/(I$5:I$24<=L$5:L$24),$A$5:$A$24)+1)) | M43: =IF(SUMPRODUCT(--(I$5:I$24<=M$5:M$24))=0,"siempre",IF(LOOKUP(2,1/(I$5:I$24<=M$5:M$24),$A$5:$A$24)>=2046,"nunca",LOOKUP(2,1/(I$5:I$24<=M$5:M$24),$A$5:$A$24)+1)) | N43: =IF(SUMPRODUCT(--(I$5:I$24<=N$5:N$24))=0,"siempre",IF(LOOKUP(2,1/(I$5:I$24<=N$5:N$24),$A$5:$A$24)>=2046,"nunca",LOOKUP(2,1/(I$5:I$24<=N$5:N$24),$A$5:$A$24)+1)) | O43: =IF(SUMPRODUCT(--(I$5:I$24<=O$5:O$24))=0,"siempre",IF(LOOKUP(2,1/(I$5:I$24<=O$5:O$24),$A$5:$A$24)>=2046,"nunca",LOOKUP(2,1/(I$5:I$24<=O$5:O$24),$A$5:$A$24)+1)) | P43: =IF(SUMPRODUCT(--(I$5:I$24<=P$5:P$24))=0,"siempre",IF(LOOKUP(2,1/(I$5:I$24<=P$5:P$24),$A$5:$A$24)>=2046,"nunca",LOOKUP(2,1/(I$5:I$24<=P$5:P$24),$A$5:$A$24)+1))
A44: A7b · ICU → Travel → CRNA | B44: =IF(SUMPRODUCT(--(J$5:J$24<=B$5:B$24))=0,"siempre",IF(LOOKUP(2,1/(J$5:J$24<=B$5:B$24),$A$5:$A$24)>=2046,"nunca",LOOKUP(2,1/(J$5:J$24<=B$5:B$24),$A$5:$A$24)+1)) | C44: =IF(SUMPRODUCT(--(J$5:J$24<=C$5:C$24))=0,"siempre",IF(LOOKUP(2,1/(J$5:J$24<=C$5:C$24),$A$5:$A$24)>=2046,"nunca",LOOKUP(2,1/(J$5:J$24<=C$5:C$24),$A$5:$A$24)+1)) | D44: =IF(SUMPRODUCT(--(J$5:J$24<=D$5:D$24))=0,"siempre",IF(LOOKUP(2,1/(J$5:J$24<=D$5:D$24),$A$5:$A$24)>=2046,"nunca",LOOKUP(2,1/(J$5:J$24<=D$5:D$24),$A$5:$A$24)+1)) | E44: =IF(SUMPRODUCT(--(J$5:J$24<=E$5:E$24))=0,"siempre",IF(LOOKUP(2,1/(J$5:J$24<=E$5:E$24),$A$5:$A$24)>=2046,"nunca",LOOKUP(2,1/(J$5:J$24<=E$5:E$24),$A$5:$A$24)+1)) | F44: =IF(SUMPRODUCT(--(J$5:J$24<=F$5:F$24))=0,"siempre",IF(LOOKUP(2,1/(J$5:J$24<=F$5:F$24),$A$5:$A$24)>=2046,"nunca",LOOKUP(2,1/(J$5:J$24<=F$5:F$24),$A$5:$A$24)+1)) | G44: =IF(SUMPRODUCT(--(J$5:J$24<=G$5:G$24))=0,"siempre",IF(LOOKUP(2,1/(J$5:J$24<=G$5:G$24),$A$5:$A$24)>=2046,"nunca",LOOKUP(2,1/(J$5:J$24<=G$5:G$24),$A$5:$A$24)+1)) | H44: =IF(SUMPRODUCT(--(J$5:J$24<=H$5:H$24))=0,"siempre",IF(LOOKUP(2,1/(J$5:J$24<=H$5:H$24),$A$5:$A$24)>=2046,"nunca",LOOKUP(2,1/(J$5:J$24<=H$5:H$24),$A$5:$A$24)+1)) | I44: =IF(SUMPRODUCT(--(J$5:J$24<=I$5:I$24))=0,"siempre",IF(LOOKUP(2,1/(J$5:J$24<=I$5:I$24),$A$5:$A$24)>=2046,"nunca",LOOKUP(2,1/(J$5:J$24<=I$5:I$24),$A$5:$A$24)+1)) | J44: — | K44: =IF(SUMPRODUCT(--(J$5:J$24<=K$5:K$24))=0,"siempre",IF(LOOKUP(2,1/(J$5:J$24<=K$5:K$24),$A$5:$A$24)>=2046,"nunca",LOOKUP(2,1/(J$5:J$24<=K$5:K$24),$A$5:$A$24)+1)) | L44: =IF(SUMPRODUCT(--(J$5:J$24<=L$5:L$24))=0,"siempre",IF(LOOKUP(2,1/(J$5:J$24<=L$5:L$24),$A$5:$A$24)>=2046,"nunca",LOOKUP(2,1/(J$5:J$24<=L$5:L$24),$A$5:$A$24)+1)) | M44: =IF(SUMPRODUCT(--(J$5:J$24<=M$5:M$24))=0,"siempre",IF(LOOKUP(2,1/(J$5:J$24<=M$5:M$24),$A$5:$A$24)>=2046,"nunca",LOOKUP(2,1/(J$5:J$24<=M$5:M$24),$A$5:$A$24)+1)) | N44: =IF(SUMPRODUCT(--(J$5:J$24<=N$5:N$24))=0,"siempre",IF(LOOKUP(2,1/(J$5:J$24<=N$5:N$24),$A$5:$A$24)>=2046,"nunca",LOOKUP(2,1/(J$5:J$24<=N$5:N$24),$A$5:$A$24)+1)) | O44: =IF(SUMPRODUCT(--(J$5:J$24<=O$5:O$24))=0,"siempre",IF(LOOKUP(2,1/(J$5:J$24<=O$5:O$24),$A$5:$A$24)>=2046,"nunca",LOOKUP(2,1/(J$5:J$24<=O$5:O$24),$A$5:$A$24)+1)) | P44: =IF(SUMPRODUCT(--(J$5:J$24<=P$5:P$24))=0,"siempre",IF(LOOKUP(2,1/(J$5:J$24<=P$5:P$24),$A$5:$A$24)>=2046,"nunca",LOOKUP(2,1/(J$5:J$24<=P$5:P$24),$A$5:$A$24)+1))
A45: A8 · NP familiar (FNP) | B45: =IF(SUMPRODUCT(--(K$5:K$24<=B$5:B$24))=0,"siempre",IF(LOOKUP(2,1/(K$5:K$24<=B$5:B$24),$A$5:$A$24)>=2046,"nunca",LOOKUP(2,1/(K$5:K$24<=B$5:B$24),$A$5:$A$24)+1)) | C45: =IF(SUMPRODUCT(--(K$5:K$24<=C$5:C$24))=0,"siempre",IF(LOOKUP(2,1/(K$5:K$24<=C$5:C$24),$A$5:$A$24)>=2046,"nunca",LOOKUP(2,1/(K$5:K$24<=C$5:C$24),$A$5:$A$24)+1)) | D45: =IF(SUMPRODUCT(--(K$5:K$24<=D$5:D$24))=0,"siempre",IF(LOOKUP(2,1/(K$5:K$24<=D$5:D$24),$A$5:$A$24)>=2046,"nunca",LOOKUP(2,1/(K$5:K$24<=D$5:D$24),$A$5:$A$24)+1)) | E45: =IF(SUMPRODUCT(--(K$5:K$24<=E$5:E$24))=0,"siempre",IF(LOOKUP(2,1/(K$5:K$24<=E$5:E$24),$A$5:$A$24)>=2046,"nunca",LOOKUP(2,1/(K$5:K$24<=E$5:E$24),$A$5:$A$24)+1)) | F45: =IF(SUMPRODUCT(--(K$5:K$24<=F$5:F$24))=0,"siempre",IF(LOOKUP(2,1/(K$5:K$24<=F$5:F$24),$A$5:$A$24)>=2046,"nunca",LOOKUP(2,1/(K$5:K$24<=F$5:F$24),$A$5:$A$24)+1)) | G45: =IF(SUMPRODUCT(--(K$5:K$24<=G$5:G$24))=0,"siempre",IF(LOOKUP(2,1/(K$5:K$24<=G$5:G$24),$A$5:$A$24)>=2046,"nunca",LOOKUP(2,1/(K$5:K$24<=G$5:G$24),$A$5:$A$24)+1)) | H45: =IF(SUMPRODUCT(--(K$5:K$24<=H$5:H$24))=0,"siempre",IF(LOOKUP(2,1/(K$5:K$24<=H$5:H$24),$A$5:$A$24)>=2046,"nunca",LOOKUP(2,1/(K$5:K$24<=H$5:H$24),$A$5:$A$24)+1)) | I45: =IF(SUMPRODUCT(--(K$5:K$24<=I$5:I$24))=0,"siempre",IF(LOOKUP(2,1/(K$5:K$24<=I$5:I$24),$A$5:$A$24)>=2046,"nunca",LOOKUP(2,1/(K$5:K$24<=I$5:I$24),$A$5:$A$24)+1)) | J45: =IF(SUMPRODUCT(--(K$5:K$24<=J$5:J$24))=0,"siempre",IF(LOOKUP(2,1/(K$5:K$24<=J$5:J$24),$A$5:$A$24)>=2046,"nunca",LOOKUP(2,1/(K$5:K$24<=J$5:J$24),$A$5:$A$24)+1)) | K45: — | L45: =IF(SUMPRODUCT(--(K$5:K$24<=L$5:L$24))=0,"siempre",IF(LOOKUP(2,1/(K$5:K$24<=L$5:L$24),$A$5:$A$24)>=2046,"nunca",LOOKUP(2,1/(K$5:K$24<=L$5:L$24),$A$5:$A$24)+1)) | M45: =IF(SUMPRODUCT(--(K$5:K$24<=M$5:M$24))=0,"siempre",IF(LOOKUP(2,1/(K$5:K$24<=M$5:M$24),$A$5:$A$24)>=2046,"nunca",LOOKUP(2,1/(K$5:K$24<=M$5:M$24),$A$5:$A$24)+1)) | N45: =IF(SUMPRODUCT(--(K$5:K$24<=N$5:N$24))=0,"siempre",IF(LOOKUP(2,1/(K$5:K$24<=N$5:N$24),$A$5:$A$24)>=2046,"nunca",LOOKUP(2,1/(K$5:K$24<=N$5:N$24),$A$5:$A$24)+1)) | O45: =IF(SUMPRODUCT(--(K$5:K$24<=O$5:O$24))=0,"siempre",IF(LOOKUP(2,1/(K$5:K$24<=O$5:O$24),$A$5:$A$24)>=2046,"nunca",LOOKUP(2,1/(K$5:K$24<=O$5:O$24),$A$5:$A$24)+1)) | P45: =IF(SUMPRODUCT(--(K$5:K$24<=P$5:P$24))=0,"siempre",IF(LOOKUP(2,1/(K$5:K$24<=P$5:P$24),$A$5:$A$24)>=2046,"nunca",LOOKUP(2,1/(K$5:K$24<=P$5:P$24),$A$5:$A$24)+1))
A46: A8b · NP psiquiátrico (PMHNP) | B46: =IF(SUMPRODUCT(--(L$5:L$24<=B$5:B$24))=0,"siempre",IF(LOOKUP(2,1/(L$5:L$24<=B$5:B$24),$A$5:$A$24)>=2046,"nunca",LOOKUP(2,1/(L$5:L$24<=B$5:B$24),$A$5:$A$24)+1)) | C46: =IF(SUMPRODUCT(--(L$5:L$24<=C$5:C$24))=0,"siempre",IF(LOOKUP(2,1/(L$5:L$24<=C$5:C$24),$A$5:$A$24)>=2046,"nunca",LOOKUP(2,1/(L$5:L$24<=C$5:C$24),$A$5:$A$24)+1)) | D46: =IF(SUMPRODUCT(--(L$5:L$24<=D$5:D$24))=0,"siempre",IF(LOOKUP(2,1/(L$5:L$24<=D$5:D$24),$A$5:$A$24)>=2046,"nunca",LOOKUP(2,1/(L$5:L$24<=D$5:D$24),$A$5:$A$24)+1)) | E46: =IF(SUMPRODUCT(--(L$5:L$24<=E$5:E$24))=0,"siempre",IF(LOOKUP(2,1/(L$5:L$24<=E$5:E$24),$A$5:$A$24)>=2046,"nunca",LOOKUP(2,1/(L$5:L$24<=E$5:E$24),$A$5:$A$24)+1)) | F46: =IF(SUMPRODUCT(--(L$5:L$24<=F$5:F$24))=0,"siempre",IF(LOOKUP(2,1/(L$5:L$24<=F$5:F$24),$A$5:$A$24)>=2046,"nunca",LOOKUP(2,1/(L$5:L$24<=F$5:F$24),$A$5:$A$24)+1)) | G46: =IF(SUMPRODUCT(--(L$5:L$24<=G$5:G$24))=0,"siempre",IF(LOOKUP(2,1/(L$5:L$24<=G$5:G$24),$A$5:$A$24)>=2046,"nunca",LOOKUP(2,1/(L$5:L$24<=G$5:G$24),$A$5:$A$24)+1)) | H46: =IF(SUMPRODUCT(--(L$5:L$24<=H$5:H$24))=0,"siempre",IF(LOOKUP(2,1/(L$5:L$24<=H$5:H$24),$A$5:$A$24)>=2046,"nunca",LOOKUP(2,1/(L$5:L$24<=H$5:H$24),$A$5:$A$24)+1)) | I46: =IF(SUMPRODUCT(--(L$5:L$24<=I$5:I$24))=0,"siempre",IF(LOOKUP(2,1/(L$5:L$24<=I$5:I$24),$A$5:$A$24)>=2046,"nunca",LOOKUP(2,1/(L$5:L$24<=I$5:I$24),$A$5:$A$24)+1)) | J46: =IF(SUMPRODUCT(--(L$5:L$24<=J$5:J$24))=0,"siempre",IF(LOOKUP(2,1/(L$5:L$24<=J$5:J$24),$A$5:$A$24)>=2046,"nunca",LOOKUP(2,1/(L$5:L$24<=J$5:J$24),$A$5:$A$24)+1)) | K46: =IF(SUMPRODUCT(--(L$5:L$24<=K$5:K$24))=0,"siempre",IF(LOOKUP(2,1/(L$5:L$24<=K$5:K$24),$A$5:$A$24)>=2046,"nunca",LOOKUP(2,1/(L$5:L$24<=K$5:K$24),$A$5:$A$24)+1)) | L46: — | M46: =IF(SUMPRODUCT(--(L$5:L$24<=M$5:M$24))=0,"siempre",IF(LOOKUP(2,1/(L$5:L$24<=M$5:M$24),$A$5:$A$24)>=2046,"nunca",LOOKUP(2,1/(L$5:L$24<=M$5:M$24),$A$5:$A$24)+1)) | N46: =IF(SUMPRODUCT(--(L$5:L$24<=N$5:N$24))=0,"siempre",IF(LOOKUP(2,1/(L$5:L$24<=N$5:N$24),$A$5:$A$24)>=2046,"nunca",LOOKUP(2,1/(L$5:L$24<=N$5:N$24),$A$5:$A$24)+1)) | O46: =IF(SUMPRODUCT(--(L$5:L$24<=O$5:O$24))=0,"siempre",IF(LOOKUP(2,1/(L$5:L$24<=O$5:O$24),$A$5:$A$24)>=2046,"nunca",LOOKUP(2,1/(L$5:L$24<=O$5:O$24),$A$5:$A$24)+1)) | P46: =IF(SUMPRODUCT(--(L$5:L$24<=P$5:P$24))=0,"siempre",IF(LOOKUP(2,1/(L$5:L$24<=P$5:P$24),$A$5:$A$24)>=2046,"nunca",LOOKUP(2,1/(L$5:L$24<=P$5:P$24),$A$5:$A$24)+1))
A47: B1 · MD: match al primer intento | B47: =IF(SUMPRODUCT(--(M$5:M$24<=B$5:B$24))=0,"siempre",IF(LOOKUP(2,1/(M$5:M$24<=B$5:B$24),$A$5:$A$24)>=2046,"nunca",LOOKUP(2,1/(M$5:M$24<=B$5:B$24),$A$5:$A$24)+1)) | C47: =IF(SUMPRODUCT(--(M$5:M$24<=C$5:C$24))=0,"siempre",IF(LOOKUP(2,1/(M$5:M$24<=C$5:C$24),$A$5:$A$24)>=2046,"nunca",LOOKUP(2,1/(M$5:M$24<=C$5:C$24),$A$5:$A$24)+1)) | D47: =IF(SUMPRODUCT(--(M$5:M$24<=D$5:D$24))=0,"siempre",IF(LOOKUP(2,1/(M$5:M$24<=D$5:D$24),$A$5:$A$24)>=2046,"nunca",LOOKUP(2,1/(M$5:M$24<=D$5:D$24),$A$5:$A$24)+1)) | E47: =IF(SUMPRODUCT(--(M$5:M$24<=E$5:E$24))=0,"siempre",IF(LOOKUP(2,1/(M$5:M$24<=E$5:E$24),$A$5:$A$24)>=2046,"nunca",LOOKUP(2,1/(M$5:M$24<=E$5:E$24),$A$5:$A$24)+1)) | F47: =IF(SUMPRODUCT(--(M$5:M$24<=F$5:F$24))=0,"siempre",IF(LOOKUP(2,1/(M$5:M$24<=F$5:F$24),$A$5:$A$24)>=2046,"nunca",LOOKUP(2,1/(M$5:M$24<=F$5:F$24),$A$5:$A$24)+1)) | G47: =IF(SUMPRODUCT(--(M$5:M$24<=G$5:G$24))=0,"siempre",IF(LOOKUP(2,1/(M$5:M$24<=G$5:G$24),$A$5:$A$24)>=2046,"nunca",LOOKUP(2,1/(M$5:M$24<=G$5:G$24),$A$5:$A$24)+1)) | H47: =IF(SUMPRODUCT(--(M$5:M$24<=H$5:H$24))=0,"siempre",IF(LOOKUP(2,1/(M$5:M$24<=H$5:H$24),$A$5:$A$24)>=2046,"nunca",LOOKUP(2,1/(M$5:M$24<=H$5:H$24),$A$5:$A$24)+1)) | I47: =IF(SUMPRODUCT(--(M$5:M$24<=I$5:I$24))=0,"siempre",IF(LOOKUP(2,1/(M$5:M$24<=I$5:I$24),$A$5:$A$24)>=2046,"nunca",LOOKUP(2,1/(M$5:M$24<=I$5:I$24),$A$5:$A$24)+1)) | J47: =IF(SUMPRODUCT(--(M$5:M$24<=J$5:J$24))=0,"siempre",IF(LOOKUP(2,1/(M$5:M$24<=J$5:J$24),$A$5:$A$24)>=2046,"nunca",LOOKUP(2,1/(M$5:M$24<=J$5:J$24),$A$5:$A$24)+1)) | K47: =IF(SUMPRODUCT(--(M$5:M$24<=K$5:K$24))=0,"siempre",IF(LOOKUP(2,1/(M$5:M$24<=K$5:K$24),$A$5:$A$24)>=2046,"nunca",LOOKUP(2,1/(M$5:M$24<=K$5:K$24),$A$5:$A$24)+1)) | L47: =IF(SUMPRODUCT(--(M$5:M$24<=L$5:L$24))=0,"siempre",IF(LOOKUP(2,1/(M$5:M$24<=L$5:L$24),$A$5:$A$24)>=2046,"nunca",LOOKUP(2,1/(M$5:M$24<=L$5:L$24),$A$5:$A$24)+1)) | M47: — | N47: =IF(SUMPRODUCT(--(M$5:M$24<=N$5:N$24))=0,"siempre",IF(LOOKUP(2,1/(M$5:M$24<=N$5:N$24),$A$5:$A$24)>=2046,"nunca",LOOKUP(2,1/(M$5:M$24<=N$5:N$24),$A$5:$A$24)+1)) | O47: =IF(SUMPRODUCT(--(M$5:M$24<=O$5:O$24))=0,"siempre",IF(LOOKUP(2,1/(M$5:M$24<=O$5:O$24),$A$5:$A$24)>=2046,"nunca",LOOKUP(2,1/(M$5:M$24<=O$5:O$24),$A$5:$A$24)+1)) | P47: =IF(SUMPRODUCT(--(M$5:M$24<=P$5:P$24))=0,"siempre",IF(LOOKUP(2,1/(M$5:M$24<=P$5:P$24),$A$5:$A$24)>=2046,"nunca",LOOKUP(2,1/(M$5:M$24<=P$5:P$24),$A$5:$A$24)+1))
A48: B2 · MD: SOAP preliminar → categórico | B48: =IF(SUMPRODUCT(--(N$5:N$24<=B$5:B$24))=0,"siempre",IF(LOOKUP(2,1/(N$5:N$24<=B$5:B$24),$A$5:$A$24)>=2046,"nunca",LOOKUP(2,1/(N$5:N$24<=B$5:B$24),$A$5:$A$24)+1)) | C48: =IF(SUMPRODUCT(--(N$5:N$24<=C$5:C$24))=0,"siempre",IF(LOOKUP(2,1/(N$5:N$24<=C$5:C$24),$A$5:$A$24)>=2046,"nunca",LOOKUP(2,1/(N$5:N$24<=C$5:C$24),$A$5:$A$24)+1)) | D48: =IF(SUMPRODUCT(--(N$5:N$24<=D$5:D$24))=0,"siempre",IF(LOOKUP(2,1/(N$5:N$24<=D$5:D$24),$A$5:$A$24)>=2046,"nunca",LOOKUP(2,1/(N$5:N$24<=D$5:D$24),$A$5:$A$24)+1)) | E48: =IF(SUMPRODUCT(--(N$5:N$24<=E$5:E$24))=0,"siempre",IF(LOOKUP(2,1/(N$5:N$24<=E$5:E$24),$A$5:$A$24)>=2046,"nunca",LOOKUP(2,1/(N$5:N$24<=E$5:E$24),$A$5:$A$24)+1)) | F48: =IF(SUMPRODUCT(--(N$5:N$24<=F$5:F$24))=0,"siempre",IF(LOOKUP(2,1/(N$5:N$24<=F$5:F$24),$A$5:$A$24)>=2046,"nunca",LOOKUP(2,1/(N$5:N$24<=F$5:F$24),$A$5:$A$24)+1)) | G48: =IF(SUMPRODUCT(--(N$5:N$24<=G$5:G$24))=0,"siempre",IF(LOOKUP(2,1/(N$5:N$24<=G$5:G$24),$A$5:$A$24)>=2046,"nunca",LOOKUP(2,1/(N$5:N$24<=G$5:G$24),$A$5:$A$24)+1)) | H48: =IF(SUMPRODUCT(--(N$5:N$24<=H$5:H$24))=0,"siempre",IF(LOOKUP(2,1/(N$5:N$24<=H$5:H$24),$A$5:$A$24)>=2046,"nunca",LOOKUP(2,1/(N$5:N$24<=H$5:H$24),$A$5:$A$24)+1)) | I48: =IF(SUMPRODUCT(--(N$5:N$24<=I$5:I$24))=0,"siempre",IF(LOOKUP(2,1/(N$5:N$24<=I$5:I$24),$A$5:$A$24)>=2046,"nunca",LOOKUP(2,1/(N$5:N$24<=I$5:I$24),$A$5:$A$24)+1)) | J48: =IF(SUMPRODUCT(--(N$5:N$24<=J$5:J$24))=0,"siempre",IF(LOOKUP(2,1/(N$5:N$24<=J$5:J$24),$A$5:$A$24)>=2046,"nunca",LOOKUP(2,1/(N$5:N$24<=J$5:J$24),$A$5:$A$24)+1)) | K48: =IF(SUMPRODUCT(--(N$5:N$24<=K$5:K$24))=0,"siempre",IF(LOOKUP(2,1/(N$5:N$24<=K$5:K$24),$A$5:$A$24)>=2046,"nunca",LOOKUP(2,1/(N$5:N$24<=K$5:K$24),$A$5:$A$24)+1)) | L48: =IF(SUMPRODUCT(--(N$5:N$24<=L$5:L$24))=0,"siempre",IF(LOOKUP(2,1/(N$5:N$24<=L$5:L$24),$A$5:$A$24)>=2046,"nunca",LOOKUP(2,1/(N$5:N$24<=L$5:L$24),$A$5:$A$24)+1)) | M48: =IF(SUMPRODUCT(--(N$5:N$24<=M$5:M$24))=0,"siempre",IF(LOOKUP(2,1/(N$5:N$24<=M$5:M$24),$A$5:$A$24)>=2046,"nunca",LOOKUP(2,1/(N$5:N$24<=M$5:M$24),$A$5:$A$24)+1)) | N48: — | O48: =IF(SUMPRODUCT(--(N$5:N$24<=O$5:O$24))=0,"siempre",IF(LOOKUP(2,1/(N$5:N$24<=O$5:O$24),$A$5:$A$24)>=2046,"nunca",LOOKUP(2,1/(N$5:N$24<=O$5:O$24),$A$5:$A$24)+1)) | P48: =IF(SUMPRODUCT(--(N$5:N$24<=P$5:P$24))=0,"siempre",IF(LOOKUP(2,1/(N$5:N$24<=P$5:P$24),$A$5:$A$24)>=2046,"nunca",LOOKUP(2,1/(N$5:N$24<=P$5:P$24),$A$5:$A$24)+1))
A49: B3 · MD: no match → match al reintento | B49: =IF(SUMPRODUCT(--(O$5:O$24<=B$5:B$24))=0,"siempre",IF(LOOKUP(2,1/(O$5:O$24<=B$5:B$24),$A$5:$A$24)>=2046,"nunca",LOOKUP(2,1/(O$5:O$24<=B$5:B$24),$A$5:$A$24)+1)) | C49: =IF(SUMPRODUCT(--(O$5:O$24<=C$5:C$24))=0,"siempre",IF(LOOKUP(2,1/(O$5:O$24<=C$5:C$24),$A$5:$A$24)>=2046,"nunca",LOOKUP(2,1/(O$5:O$24<=C$5:C$24),$A$5:$A$24)+1)) | D49: =IF(SUMPRODUCT(--(O$5:O$24<=D$5:D$24))=0,"siempre",IF(LOOKUP(2,1/(O$5:O$24<=D$5:D$24),$A$5:$A$24)>=2046,"nunca",LOOKUP(2,1/(O$5:O$24<=D$5:D$24),$A$5:$A$24)+1)) | E49: =IF(SUMPRODUCT(--(O$5:O$24<=E$5:E$24))=0,"siempre",IF(LOOKUP(2,1/(O$5:O$24<=E$5:E$24),$A$5:$A$24)>=2046,"nunca",LOOKUP(2,1/(O$5:O$24<=E$5:E$24),$A$5:$A$24)+1)) | F49: =IF(SUMPRODUCT(--(O$5:O$24<=F$5:F$24))=0,"siempre",IF(LOOKUP(2,1/(O$5:O$24<=F$5:F$24),$A$5:$A$24)>=2046,"nunca",LOOKUP(2,1/(O$5:O$24<=F$5:F$24),$A$5:$A$24)+1)) | G49: =IF(SUMPRODUCT(--(O$5:O$24<=G$5:G$24))=0,"siempre",IF(LOOKUP(2,1/(O$5:O$24<=G$5:G$24),$A$5:$A$24)>=2046,"nunca",LOOKUP(2,1/(O$5:O$24<=G$5:G$24),$A$5:$A$24)+1)) | H49: =IF(SUMPRODUCT(--(O$5:O$24<=H$5:H$24))=0,"siempre",IF(LOOKUP(2,1/(O$5:O$24<=H$5:H$24),$A$5:$A$24)>=2046,"nunca",LOOKUP(2,1/(O$5:O$24<=H$5:H$24),$A$5:$A$24)+1)) | I49: =IF(SUMPRODUCT(--(O$5:O$24<=I$5:I$24))=0,"siempre",IF(LOOKUP(2,1/(O$5:O$24<=I$5:I$24),$A$5:$A$24)>=2046,"nunca",LOOKUP(2,1/(O$5:O$24<=I$5:I$24),$A$5:$A$24)+1)) | J49: =IF(SUMPRODUCT(--(O$5:O$24<=J$5:J$24))=0,"siempre",IF(LOOKUP(2,1/(O$5:O$24<=J$5:J$24),$A$5:$A$24)>=2046,"nunca",LOOKUP(2,1/(O$5:O$24<=J$5:J$24),$A$5:$A$24)+1)) | K49: =IF(SUMPRODUCT(--(O$5:O$24<=K$5:K$24))=0,"siempre",IF(LOOKUP(2,1/(O$5:O$24<=K$5:K$24),$A$5:$A$24)>=2046,"nunca",LOOKUP(2,1/(O$5:O$24<=K$5:K$24),$A$5:$A$24)+1)) | L49: =IF(SUMPRODUCT(--(O$5:O$24<=L$5:L$24))=0,"siempre",IF(LOOKUP(2,1/(O$5:O$24<=L$5:L$24),$A$5:$A$24)>=2046,"nunca",LOOKUP(2,1/(O$5:O$24<=L$5:L$24),$A$5:$A$24)+1)) | M49: =IF(SUMPRODUCT(--(O$5:O$24<=M$5:M$24))=0,"siempre",IF(LOOKUP(2,1/(O$5:O$24<=M$5:M$24),$A$5:$A$24)>=2046,"nunca",LOOKUP(2,1/(O$5:O$24<=M$5:M$24),$A$5:$A$24)+1)) | N49: =IF(SUMPRODUCT(--(O$5:O$24<=N$5:N$24))=0,"siempre",IF(LOOKUP(2,1/(O$5:O$24<=N$5:N$24),$A$5:$A$24)>=2046,"nunca",LOOKUP(2,1/(O$5:O$24<=N$5:N$24),$A$5:$A$24)+1)) | O49: — | P49: =IF(SUMPRODUCT(--(O$5:O$24<=P$5:P$24))=0,"siempre",IF(LOOKUP(2,1/(O$5:O$24<=P$5:P$24),$A$5:$A$24)>=2046,"nunca",LOOKUP(2,1/(O$5:O$24<=P$5:P$24),$A$5:$A$24)+1))
A50: B4 · MD: nunca hace match → vuelve a CDI | B50: =IF(SUMPRODUCT(--(P$5:P$24<=B$5:B$24))=0,"siempre",IF(LOOKUP(2,1/(P$5:P$24<=B$5:B$24),$A$5:$A$24)>=2046,"nunca",LOOKUP(2,1/(P$5:P$24<=B$5:B$24),$A$5:$A$24)+1)) | C50: =IF(SUMPRODUCT(--(P$5:P$24<=C$5:C$24))=0,"siempre",IF(LOOKUP(2,1/(P$5:P$24<=C$5:C$24),$A$5:$A$24)>=2046,"nunca",LOOKUP(2,1/(P$5:P$24<=C$5:C$24),$A$5:$A$24)+1)) | D50: =IF(SUMPRODUCT(--(P$5:P$24<=D$5:D$24))=0,"siempre",IF(LOOKUP(2,1/(P$5:P$24<=D$5:D$24),$A$5:$A$24)>=2046,"nunca",LOOKUP(2,1/(P$5:P$24<=D$5:D$24),$A$5:$A$24)+1)) | E50: =IF(SUMPRODUCT(--(P$5:P$24<=E$5:E$24))=0,"siempre",IF(LOOKUP(2,1/(P$5:P$24<=E$5:E$24),$A$5:$A$24)>=2046,"nunca",LOOKUP(2,1/(P$5:P$24<=E$5:E$24),$A$5:$A$24)+1)) | F50: =IF(SUMPRODUCT(--(P$5:P$24<=F$5:F$24))=0,"siempre",IF(LOOKUP(2,1/(P$5:P$24<=F$5:F$24),$A$5:$A$24)>=2046,"nunca",LOOKUP(2,1/(P$5:P$24<=F$5:F$24),$A$5:$A$24)+1)) | G50: =IF(SUMPRODUCT(--(P$5:P$24<=G$5:G$24))=0,"siempre",IF(LOOKUP(2,1/(P$5:P$24<=G$5:G$24),$A$5:$A$24)>=2046,"nunca",LOOKUP(2,1/(P$5:P$24<=G$5:G$24),$A$5:$A$24)+1)) | H50: =IF(SUMPRODUCT(--(P$5:P$24<=H$5:H$24))=0,"siempre",IF(LOOKUP(2,1/(P$5:P$24<=H$5:H$24),$A$5:$A$24)>=2046,"nunca",LOOKUP(2,1/(P$5:P$24<=H$5:H$24),$A$5:$A$24)+1)) | I50: =IF(SUMPRODUCT(--(P$5:P$24<=I$5:I$24))=0,"siempre",IF(LOOKUP(2,1/(P$5:P$24<=I$5:I$24),$A$5:$A$24)>=2046,"nunca",LOOKUP(2,1/(P$5:P$24<=I$5:I$24),$A$5:$A$24)+1)) | J50: =IF(SUMPRODUCT(--(P$5:P$24<=J$5:J$24))=0,"siempre",IF(LOOKUP(2,1/(P$5:P$24<=J$5:J$24),$A$5:$A$24)>=2046,"nunca",LOOKUP(2,1/(P$5:P$24<=J$5:J$24),$A$5:$A$24)+1)) | K50: =IF(SUMPRODUCT(--(P$5:P$24<=K$5:K$24))=0,"siempre",IF(LOOKUP(2,1/(P$5:P$24<=K$5:K$24),$A$5:$A$24)>=2046,"nunca",LOOKUP(2,1/(P$5:P$24<=K$5:K$24),$A$5:$A$24)+1)) | L50: =IF(SUMPRODUCT(--(P$5:P$24<=L$5:L$24))=0,"siempre",IF(LOOKUP(2,1/(P$5:P$24<=L$5:L$24),$A$5:$A$24)>=2046,"nunca",LOOKUP(2,1/(P$5:P$24<=L$5:L$24),$A$5:$A$24)+1)) | M50: =IF(SUMPRODUCT(--(P$5:P$24<=M$5:M$24))=0,"siempre",IF(LOOKUP(2,1/(P$5:P$24<=M$5:M$24),$A$5:$A$24)>=2046,"nunca",LOOKUP(2,1/(P$5:P$24<=M$5:M$24),$A$5:$A$24)+1)) | N50: =IF(SUMPRODUCT(--(P$5:P$24<=N$5:N$24))=0,"siempre",IF(LOOKUP(2,1/(P$5:P$24<=N$5:N$24),$A$5:$A$24)>=2046,"nunca",LOOKUP(2,1/(P$5:P$24<=N$5:N$24),$A$5:$A$24)+1)) | O50: =IF(SUMPRODUCT(--(P$5:P$24<=O$5:O$24))=0,"siempre",IF(LOOKUP(2,1/(P$5:P$24<=O$5:O$24),$A$5:$A$24)>=2046,"nunca",LOOKUP(2,1/(P$5:P$24<=O$5:O$24),$A$5:$A$24)+1)) | P50: —
A52: Notas
...

Sheet Ubic_miami
A1: Miami / Sur de Florida
A2: Seguros muy caros; dúplex escasos y caros; mamá y tía tendrían que mudarse desde DFW.
A3: Licencia compacta: Válida: FL es estado NLC. Ojo: viviendo en FL tu licencia multiestado debería ser de FL (estado de residencia primaria), no la de TX.
A5: Parámetro | B5: Valor | C5: Unidad | D5: Fuente | E5: Confianza | F5: Estimado
A6: Factor salarial RN vs nacional | B6: 0.937 | C6: x | D6: RN Miami-Fort Lauderdale (BLS OEWS 2025 vía Hyring: media $94,990) | E6: media
A7: Factor salarial médico vs nacional | B7: 0.97 | C7: x | D7: Doximity Physician Compensation Report 2026 | E7: baja | F7: sí
A8: Salario PGY-1 2026 | B8: 67400 | C8: $ | D8: Encuesta AAMC 2025 de salarios de residentes por región (vía MedSchoolCoach) | E8: media
A9: Gastos de vida anuales (sin vivienda) | B9: 31000 | C9: $ | D9: Estimación propia del modelo (sin dato publicado directo); ver nota | E9: baja | F9: sí
A10: Renta propia mensual antes de comprar (1 hab.) | B10: 2250 | C10: $ | D10: Estimación propia del modelo (sin dato publicado directo); ver nota | E10: baja | F10: sí
A11: Seguro de vivienda (% del valor/año) | B11: 0.013 | C11: % | D11: Insurance.com 2026: prima promedio FL $8,471; TX $4,582; nacional $2,872 | E11: media | F11: sí
A12: Impuesto a la propiedad efectivo | B12: 0.016 | C12: % | D12: Estimación propia del modelo (sin dato publicado directo); ver nota | E12: baja | F12: sí
A13: Facilidad de match IMG si te limitas a la región | B13: 0.85 | C13: x | D13: Estimación propia del modelo (sin dato publicado directo); ver nota | E13: baja | F13: sí
A14: Renta mensual por unidad rentada (multifamiliar) | B14: 2300 | C14: $ | D14: Estimación propia del modelo (sin dato publicado directo); ver nota | E14: baja | F14: sí
A15: Precio dúplex | B15: 850000 | C15: $ | D15: Miami-Dade unifamiliar mediana $692k (sep-2026, Echo Fine Properties) | E15: baja | F15: sí
A16: Precio casa con in-law suite | B16: 950000 | C16: $ | D16: Miami-Dade unifamiliar mediana $692k (sep-2026, Echo Fine Properties) | E16: baja | F16: sí
A17: Precio dos casas pequeñas (total) | B17: 1150000 | C17: $ | D17: Miami-Dade unifamiliar mediana $692k (sep-2026, Echo Fine Properties) | E17: baja | F17: sí
A18: Precio casa (sin ADU) | B18: 700000 | C18: $ | D18: Miami-Dade unifamiliar mediana $692k (sep-2026, Echo Fine Properties) | E18: media | F18: sí
A19: Costo de construir ADU | B19: 180000 | C19: $ | D19: Estimación propia del modelo (sin dato publicado directo); ver nota | E19: baja | F19: sí
A20: Precio fourplex | B20: 1500000 | C20: $ | D20: Estimación propia del modelo (sin dato publicado directo); ver nota | E20: baja | F20: sí
A21: Impuesto estatal (1=ninguno, 2=Ohio, 3=Nueva York) | B21: 1
A22: Impuesto municipal NYC (1/0) | B22: 0
A24: Cotización de vivienda (precios 2026, escenario activo)
A25: Configuración | B25: Precio | C25: Enganche | D25: Cierre | E25: Préstamo | F25: P&I mensual | G25: Impuesto/mes | H25: Seguro/mes | I25: PMI/mes | J25: Mantenimiento/mes | K25: Renta recibida/mes | L25: PITI | M25: Costo neto/mes | N25: Ingreso bruto anual necesario
A26: Dúplex (yo en una unidad, ellas en la otra) | B26: =ubic_miami_precio_duplex | C26: =B26*vivienda_enganchePct | D26: =B26*vivienda_cierrePct | E26: =B26-C26 | F26: =PMT(g_mortRate/12,vivienda_plazoHipoteca*12,-E26) | G26: =B26*ubic_miami_impuestoPropPct/12 | H26: =B26*ubic_miami_seguroPct/12 | I26: =IF(vivienda_enganchePct<0.2,E26*vivienda_pmiTasa/12,0) | J26: =B26*vivienda_mantenimientoPct/12 | K26: =0*ubic_miami_rentaUnidad*(1-vivienda_vacancia) | L26: =F26+G26+H26+I26 | M26: =L26+J26-K26*(1-vivienda_gestionPct) | N26: =12*MAX(0,L26-0.75*K26)/vivienda_dtiMax
A27: Casa grande con in-law suite | B27: =ubic_miami_precio_inlaw | C27: =B27*vivienda_enganchePct | D27: =B27*vivienda_cierrePct | E27: =B27-C27 | F27: =PMT(g_mortRate/12,vivienda_plazoHipoteca*12,-E27) | G27: =B27*ubic_miami_impuestoPropPct/12 | H27: =B27*ubic_miami_seguroPct/12 | I27: =IF(vivienda_enganchePct<0.2,E27*vivienda_pmiTasa/12,0) | J27: =B27*vivienda_mantenimientoPct/12 | K27: =0*ubic_miami_rentaUnidad*(1-vivienda_vacancia) | L27: =F27+G27+H27+I27 | M27: =L27+J27-K27*(1-vivienda_gestionPct) | N27: =12*MAX(0,L27-0.75*K27)/vivienda_dtiMax
A28: Dos casas pequeñas cercanas | B28: =ubic_miami_precio_dosCasas | C28: =B28*vivienda_enganchePct | D28: =B28*vivienda_cierrePct | E28: =B28-C28 | F28: =PMT(g_mortRate/12,vivienda_plazoHipoteca*12,-E28) | G28: =B28*ubic_miami_impuestoPropPct/12 | H28: =B28*ubic_miami_seguroPct/12 | I28: =IF(vivienda_enganchePct<0.2,E28*vivienda_pmiTasa/12,0) | J28: =B28*vivienda_mantenimientoPct/12 | K28: =0*ubic_miami_rentaUnidad*(1-vivienda_vacancia) | L28: =F28+G28+H28+I28 | M28: =L28+J28-K28*(1-vivienda_gestionPct) | N28: =12*MAX(0,L28-0.75*K28)/vivienda_dtiMax
A29: Casa + ADU construido después | B29: =ubic_miami_precio_casaAdu | C29: =B29*vivienda_enganchePct | D29: =B29*vivienda_cierrePct | E29: =B29-C29 | F29: =PMT(g_mortRate/12,vivienda_plazoHipoteca*12,-E29) | G29: =B29*ubic_miami_impuestoPropPct/12 | H29: =B29*ubic_miami_seguroPct/12 | I29: =IF(vivienda_enganchePct<0.2,E29*vivienda_pmiTasa/12,0) | J29: =B29*vivienda_mantenimientoPct/12 | K29: =0*ubic_miami_rentaUnidad*(1-vivienda_vacancia) | L29: =F29+G29+H29+I29 | M29: =L29+J29-K29*(1-vivienda_gestionPct) | N29: =12*MAX(0,L29-0.75*K29)/vivienda_dtiMax
A30: Multifamiliar 3-4 unidades (rentar 1-2) | B30: =ubic_miami_precio_multi | C30: =B30*vivienda_enganchePct | D30: =B30*vivienda_cierrePct | E30: =B30-C30 | F30: =PMT(g_mortRate/12,vivienda_plazoHipoteca*12,-E30) | G30: =B30*ubic_miami_impuestoPropPct/12 | H30: =B30*ubic_miami_seguroPct/12 | I30: =IF(vivienda_enganchePct<0.2,E30*vivienda_pmiTasa/12,0) | J30: =B30*vivienda_mantenimientoPct/12 | K30: =2*ubic_miami_rentaUnidad*(1-vivienda_vacancia) | L30: =F30+G30+H30+I30 | M30: =L30+J30-K30*(1-vivienda_gestionPct) | N30: =12*MAX(0,L30-0.75*K30)/vivienda_dtiMax

Sheet Ubic_dfw
A1: Dallas–Fort Worth
A2: Donde viven mamá y tía. Sin impuesto estatal; impuesto predial alto (~1.8–2.2%).
A3: Licencia compacta: Válida: tu licencia compacta es de TX; al mudarte TX sería tu estado de residencia (lo ideal).
A5: Parámetro | B5: Valor | C5: Unidad | D5: Fuente | E5: Confianza | F5: Estimado
A6: Factor salarial RN vs nacional | B6: 0.976 | C6: x | D6: RN DFW $101,420 / Houston $99,830 (allnurses, año BLS no claro); DFW 2024 mediana $98,740 | E6: media
A7: Factor salarial médico vs nacional | B7: 1.02 | C7: x | D7: Doximity Physician Compensation Report 2026 | E7: baja | F7: sí
A8: Salario PGY-1 2026 | B8: 67400 | C8: $ | D8: Encuesta AAMC 2025 de salarios de residentes por región (vía MedSchoolCoach) | E8: media
A9: Gastos de vida anuales (sin vivienda) | B9: 28500 | C9: $ | D9: Estimación propia del modelo (sin dato publicado directo); ver nota | E9: baja | F9: sí
